Workbook

Sheet Raw Values_Con
A1: Bottom Collumella | G1: Bottom | M1: Bottom | R1: Bottom | W1: Bottom | X1: 1607 | AB1: Bottom | AC1: 1608 | AG1: Bottom | AH1: 1609 | AL1: Bottom | AM1: 1610 | AQ1: Bottom | AR1: 1611 | AV1: Bottom | AW1: 1613 | BA1: Bottom | BB1: 1614 | BF1: Bottom | BG1: 1615 | BK1: Bottom | BL1: 1616 | BP1: Bottom | BQ1: 1617 | BU1: Bottom | BV1: 1618 | BZ1: Bottom | CA1: 1619 | CE1: Bottom | CF1: 1620 | CJ1: Bottom | CK1: 1621 | CO1: Bottom | CP1: 1622 | CT1: Bottom | CU1: 1623 | CY1: Bottom | CZ1: 1624 | DD1: Bottom | DE1: 1625 | DI1: Bottom | DJ1: 1626 | DN1: Bottom | DO1: 1627 | DS1: Bottom | DT1: 1628
A2: Image_ID | B2: Pixels | C2: R | E2: L | G2: Image_ID | H2: Pixels | I2: R | K2: L | M2: 1605 | R2: Pixels | S2: R | U2: L | W2: Pixels | X2: R | Z2: L | AB2: Pixels | AC2: R | AE2: L | AG2: Pixels | AH2: R | AJ2: L | AL2: Pixels | AM2: R | AO2: L | AQ2: Pixels | AR2: R | AT2: L | AV2: Pixels | AW2: R | AY2: L | BA2: Pixels | BB2: R | BD2: L | BF2: Pixels | BG2: R | BI2: L | BK2: Pixels | BL2: R | BN2: L | BP2: Pixels | BQ2: R | BS2: L | BU2: Pixels | BV2: R | BX2: L | BZ2: Pixels | CA2: R | CC2: L | CE2: Pixels | CF2: R | CH2: L | CJ2: Pixels | CK2: R | CM2: L | CO2: Pixels | CP2: R | CR2: L | CT2: Pixels | CU2: R | CW2: L | CY2: Pixels | CZ2: R | DB2: L | DD2: Pixels | DE2: R | DG2: L | DI2: Pixels | DJ2: R | DL2: L | DN2: Pixels | DO2: R | DQ2: L | DS2: Pixels | DT2: R | DV2: L
A3: 1603 | B3: 0 | C3: 57.7812 | D3: 29 | E3: 107.0312 | G3: 1604 | H3: 0 | I3: 32.75 | J3: C | K3: 91.1875 | M3: Pixels | N3: R | P3: L | R3: 1606 | W3: 0 | X3: 17.2083 | Y3: 44 | Z3: 58.7083 | AB3: 0 | AC3: 29 | AD3: 54 | AE3: 98.2174 | AG3: 0 | AH3: 25.4737 | AI3: 48 | AJ3: 103.9474 | AL3: 0 | AM3: 26.9412 | AN3: 36 | AO3: 75.8824 | AQ3: 0 | AR3: 18.5 | AS3: 42 | AT3: 117.2 | AV3: 0 | AW3: 28.7333 | AX3: 30 | AY3: 104.4667 | BA3: 0 | BB3: 26.8 | BC3: 45 | BD3: 107.75 | BF3: 0 | BG3: 29.3889 | BH3: 34 | BI3: 88.1111 | BK3: 0 | BL3: 29.3333 | BM3: 46 | BN3: 105.6 | BP3: 0 | BQ3: 24.7391 | BR3: 57 | BS3: 98.4348 | BU3: 0 | BV3: 26.4545 | BW3: 46 | BX3: 104.0909 | BZ3: 0 | CA3: 31.0526 | CB3: 46 | CC3: 117.1053 | CE3: 0 | CF3: 30.5714 | CG3: 43 | CH3: 101.9048 | CJ3: 0 | CK3: 9.4211 | CL3: 55 | CM3: 63 | CO3: 0 | CP3: 18.1579 | CQ3: 52 | CR3: 95.5263 | CT3: 0 | CU3: 8 | CV3: 42 | CW3: 78.9375 | CY3: 0 | CZ3: 15.3333 | DA3: 37 | DB3: 88.8 | DD3: 0 | DE3: 27.1333 | DF3: 39 | DG3: 74.7333 | DI3: 0 | DJ3: 33 | DK3: 35 | DL3: 101.6667 | DN3: 0 | DO3: 19.3125 | DP3: 46 | DQ3: 107.25 | DS3: 0 | DT3: 21.5789 | DU3: 49 | DV3: 76.7895
B4: 1 | C4: 61.0417 | D4: 30 | E4: 107.6354 | H4: 1 | I4: 33.5 | J4: 36 | K4: 91.75 | M4: 0 | N4: 23.85 | O4: 43 | P4: 97.7 | R4: 0 | S4: 29.8947 | T4: 42 | U4: 106.4737 | W4: 1 | X4: 17.75 | Y4: 45 | Z4: 55.5833 | AB4: 1 | AC4: 29.3043 | AD4: 55 | AE4: 98.3913 | AG4: 1 | AH4: 27.3158 | AI4: 49 | AJ4: 104.6316 | AL4: 1 | AM4: 28.4118 | AN4: 37 | AO4: 76.2353 | AQ4: 1 | AR4: 19 | AS4: 43 | AT4: 117.7 | AV4: 1 | AW4: 31.7333 | AX4: 31 | AY4: 102.8667 | BA4: 1 | BB4: 29.75 | BC4: 46 | BD4: 109.55 | BF4: 1 | BG4: 29.6111 | BH4: 35 | BI4: 88.8333 | BK4: 1 | BL4: 30.5333 | BM4: 47 | BN4: 105 | BP4: 1 | BQ4: 25.8261 | BR4: 58 | BS4: 99.5217 | BU4: 1 | BV4: 28 | BW4: 47 | BX4: 103.6818 | BZ4: 1 | CA4: 32.1579 | CB4: 47 | CC4: 115.5789 | CE4: 1 | CF4: 31.619 | CG4: 44 | CH4: 102.381 | CJ4: 1 | CK4: 9.7368 | CL4: 56 | CM4: 62.5789 | CO4: 1 | CP4: 18.7368 | CQ4: 53 | CR4: 94.2632 | CT4: 1 | CU4: 8.625 | CV4: 43 | CW4: 79.625 | CY4: 1 | CZ4: 17.2667 | DA4: 38 | DB4: 95.9333 | DD4: 1 | DE4: 27.2667 | DF4: 40 | DG4: 75.3333 | DI4: 1 | DJ4: 34.3333 | DK4: 36 | DL4: 102.0833 | DN4: 1 | DO4: 24.125 | DP4: 47 | DQ4: 106.1875 | DS4: 1 | DT4: 22.3158 | DU4: 50 | DV4: 76.5789
B5: 2 | C5: 63.9271 | D5: 31 | E5: 108.1146 | H5: 2 | I5: 34.375 | J5: 37 | K5: 94 | M5: 1 | N5: 25.2 | O5: 44 | P5: 95.9 | R5: 1 | S5: 32.4737 | T5: 43 | U5: 104.7895 | W5: 2 | X5: 18.375 | Y5: 46 | Z5: 52.5833 | AB5: 2 | AC5: 30.2174 | AD5: 56 | AE5: 98.087 | AG5: 2 | AH5: 30.5789 | AI5: 50 | AJ5: 104.9474 | AL5: 2 | AM5: 29.2353 | AN5: 38 | AO5: 76.5294 | AQ5: 2 | AR5: 19.85 | AS5: 44 | AT5: 116.45 | AV5: 2 | AW5: 35.3333 | AX5: 32 | AY5: 100.5333 | BA5: 2 | BB5: 34.7 | BC5: 47 | BD5: 110.1 | BF5: 2 | BG5: 30 | BH5: 36 | BI5: 88 | BK5: 2 | BL5: 33 | BM5: 48 | BN5: 104.3333 | BP5: 2 | BQ5: 27.0435 | BR5: 59 | BS5: 99.6522 | BU5: 2 | BV5: 30 | BW5: 48 | BX5: 103.8636 | BZ5: 2 | CA5: 32.9474 | CB5: 48 | CC5: 113.3684 | CE5: 2 | CF5: 32.8571 | CG5: 45 | CH5: 103.0476 | CJ5: 2 | CK5: 10.2632 | CL5: 57 | CM5: 61.6842 | CO5: 2 | CP5: 20.1053 | CQ5: 54 | CR5: 93.2632 | CT5: 2 | CU5: 9.75 | CV5: 44 | CW5: 78.8125 | CY5: 2 | CZ5: 20.2667 | DA5: 39 | DB5: 98.6667 | DD5: 2 | DE5: 27.6 | DF5: 41 | DG5: 75.6667 | DI5: 2 | DJ5: 36.3333 | DK5: 37 | DL5: 101.5 | DN5: 2 | DO5: 31.4375 | DP5: 48 | DQ5: 104.4375 | DS5: 2 | DT5: 22.7895 | DU5: 51 | DV5: 75.6316
B6: 3 | C6: 66.7083 | D6: 32 | E6: 107.1979 | H6: 3 | I6: 35.75 | J6: 38 | K6: 96.5625 | M6: 2 | N6: 27.65 | O6: 45 | P6: 93.8 | R6: 2 | S6: 34.7895 | T6: 44 | U6: 104.2632 | W6: 3 | X6: 18.9167 | Y6: 47 | Z6: 51.875 | AB6: 3 | AC6: 31.6087 | AD6: 57 | AE6: 97.5652 | AG6: 3 | AH6: 33.3158 | AI6: 51 | AJ6: 104.7895 | AL6: 3 | AM6: 29.8824 | AN6: 39 | AO6: 77.2941 | AQ6: 3 | AR6: 21 | AS6: 45 | AT6: 111.8 | AV6: 3 | AW6: 37.0667 | AX6: 33 | AY6: 100.2 | BA6: 3 | BB6: 39.2 | BC6: 48 | BD6: 108.2 | BF6: 3 | BG6: 31.5 | BH6: 37 | BI6: 86.3889 | BK6: 3 | BL6: 35.8 | BM6: 49 | BN6: 105.2667 | BP6: 3 | BQ6: 27.2609 | BR6: 60 | BS6: 99.3478 | BU6: 3 | BV6: 31.0455 | BW6: 49 | BX6: 104 | BZ6: 3 | CA6: 33.3158 | CB6: 49 | CC6: 107.4211 | CE6: 3 | CF6: 35 | CG6: 46 | CH6: 103.8571 | CJ6: 3 | CK6: 11.1579 | CL6: 58 | CM6: 61.3158 | CO6: 3 | CP6: 23.1053 | CQ6: 55 | CR6: 93.1579 | CT6: 3 | CU6: 10.6875 | CV6: 45 | CW6: 77.3125 | CY6: 3 | CZ6: 23.1333 | DA6: 40 | DB6: 97.3333 | DD6: 3 | DE6: 28 | DF6: 42 | DG6: 75.8 | DI6: 3 | DJ6: 37.9167 | DK6: 38 | DL6: 101.4167 | DN6: 3 | DO6: 38.375 | DP6: 49 | DQ6: 102.5625 | DS6: 3 | DT6: 22.8947 | DU6: 52 | DV6: 74.9474
B7: 4 | C7: 68.8438 | D7: 33 | E7: 106.5208 | H7: 4 | I7: 37.875 | J7: 39 | K7: 97.625 | M7: 3 | N7: 28.5 | O7: 46 | P7: 91.85 | R7: 3 | S7: 36.1579 | T7: 45 | U7: 105.3158 | W7: 4 | X7: 19 | Y7: 48 | Z7: 52.3333 | AB7: 4 | AC7: 32.9565 | AD7: 58 | AE7: 97.1739 | AG7: 4 | AH7: 35.7368 | AI7: 52 | AJ7: 105.0526 | AL7: 4 | AM7: 30.3529 | AN7: 40 | AO7: 77.2353 | AQ7: 4 | AR7: 22.2 | AS7: 46 | AT7: 105.55 | AV7: 4 | AW7: 38.6667 | AX7: 34 | AY7: 100.7333 | BA7: 4 | BB7: 44.7 | BC7: 49 | BD7: 106.8 | BF7: 4 | BG7: 34.3889 | BH7: 38 | BI7: 85.1667 | BK7: 4 | BL7: 38.5333 | BM7: 50 | BN7: 106.8 | BP7: 4 | BQ7: 27.2174 | BR7: 61 | BS7: 99 | BU7: 4 | BV7: 31.8636 | BW7: 50 | BX7: 104.3182 | BZ7: 4 | CA7: 34 | CB7: 50 | CC7: 99.3158 | CE7: 4 | CF7: 37.7619 | CG7: 47 | CH7: 103.8095 | CJ7: 4 | CK7: 11.8947 | CL7: 59 | CM7: 60.8947 | CO7: 4 | CP7: 26.2105 | CQ7: 56 | CR7: 93.3158 | CT7: 4 | CU7: 11.5625 | CV7: 46 | CW7: 73.8125 | CY7: 4 | CZ7: 27.4 | DA7: 41 | DB7: 95.6667 | DD7: 4 | DE7: 28.8 | DF7: 43 | DG7: 75.0667 | DI7: 4 | DJ7: 40.75 | DK7: 39 | DL7: 101.4167 | DN7: 4 | DO7: 47.9375 | DP7: 50 | DQ7: 101.4375 | DS7: 4 | DT7: 23.3158 | DU7: 53 | DV7: 74.6842
B8: 5 | C8: 69.6979 | D8: 34 | E8: 106.1042 | H8: 5 | I8: 40.5625 | J8: 40 | K8: 97.0625 | M8: 4 | N8: 29.7 | O8: 47 | P8: 91.4 | R8: 4 | S8: 37.3158 | T8: 46 | U8: 104.4211 | W8: 5 | X8: 19.1667 | Y8: 49 | Z8: 52.8333 | AB8: 5 | AC8: 34.8696 | AD8: 59 | AE8: 97 | AG8: 5 | AH8: 37.7895 | AI8: 53 | AJ8: 105 | AL8: 5 | AM8: 32.1176 | AN8: 41 | AO8: 76.5882 | AQ8: 5 | AR8: 24.8 | AS8: 47 | AT8: 101.4 | AV8: 5 | AW8: 40.9333 | AX8: 35 | AY8: 99.2667 | BA8: 5 | BB8: 48.45 | BC8: 50 | BD8: 105.55 | BF8: 5 | BG8: 38.2778 | BH8: 39 | BI8: 84.8333 | BK8: 5 | BL8: 40.7333 | BM8: 51 | BN8: 107.5333 | BP8: 5 | BQ8: 27.9565 | BR8: 62 | BS8: 98.087 | BU8: 5 | BV8: 32.9091 | BW8: 51 | BX8: 103.9091 | BZ8: 5 | CA8: 35.1579 | CB8: 51 | CC8: 92.6842 | CE8: 5 | CF8: 40.1905 | CG8: 48 | CH8: 103.9524 | CJ8: 5 | CK8: 13 | CL8: 60 | CM8: 60.0526 | CO8: 5 | CP8: 28.3158 | CQ8: 57 | CR8: 94.5789 | CT8: 5 | CU8: 12.375 | CV8: 47 | CW8: 68.5625 | CY8: 5 | CZ8: 31.1333 | DA8: 42 | DB8: 92.6 | DD8: 5 | DE8: 29.8 | DF8: 44 | DG8: 74.5333 | DI8: 5 | DJ8: 43.9167 | DK8: 40 | DL8: 101 | DN8: 5 | DO8: 56.6875 | DP8: 51 | DQ8: 101.6875 | DS8: 5 | DT8: 24.2632 | DU8: 54 | DV8: 73.7368
B9: 6 | C9: 70.9167 | D9: 35 | E9: 105.4062 | H9: 6 | I9: 42.75 | J9: 41 | K9: 97.4375 | M9: 5 | N9: 32.05 | O9: 48 | P9: 91.35 | R9: 5 | S9: 38.8421 | T9: 47 | U9: 102.3684 | W9: 6 | X9: 19.8333 | Y9: 50 | Z9: 53.1667 | AB9: 6 | AC9: 36.6087 | AD9: 60 | AE9: 96.6522 | AG9: 6 | AH9: 40.4211 | AI9: 54 | AJ9: 104.3684 | AL9: 6 | AM9: 34.2353 | AN9: 42 | AO9: 76 | AQ9: 6 | AR9: 27.7 | AS9: 48 | AT9: 99.15 | AV9: 6 | AW9: 43.1333 | AX9: 36 | AY9: 97.9333 | BA9: 6 | BB9: 49.4 | BC9: 51 | BD9: 104.6 | BF9: 6 | BG9: 42.1667 | BH9: 40 | BI9: 84.5556 | BK9: 6 | BL9: 40.8 | BM9: 52 | BN9: 106.4 | BP9: 6 | BQ9: 28.3913 | BR9: 63 | BS9: 96.3043 | BU9: 6 | BV9: 34.2727 | BW9: 52 | BX9: 103.1818 | BZ9: 6 | CA9: 36.7895 | CB9: 52 | CC9: 90.6842 | CE9: 6 | CF9: 41.9048 | CG9: 49 | CH9: 104.2381 | CJ9: 6 | CK9: 14.0526 | CL9: 61 | CM9: 59.8421 | CO9: 6 | CP9: 31.6842 | CQ9: 58 | CR9: 95.6842 | CT9: 6 | CU9: 13.5625 | CV9: 48 | CW9: 63.125 | CY9: 6 | CZ9: 32.9333 | DA9: 43 | DB9: 86.9333 | DD9: 6 | DE9: 30.5333 | DF9: 45 | DG9: 74.6 | DI9: 6 | DJ9: 46.5 | DK9: 41 | DL9: 100.25 | DN9: 6 | DO9: 63.1875 | DP9: 52 | DQ9: 101.75 | DS9: 6 | DT9: 24.9474 | DU9: 55 | DV9: 73.3684
B10: 7 | C10: 72.0521 | D10: 36 | E10: 105.4062 | H10: 7 | I10: 45.125 | J10: 42 | K10: 96.375 | M10: 6 | N10: 34.85 | O10: 49 | P10: 93.2 | R10: 6 | S10: 40.9474 | T10: 48 | U10: 100.7368 | W10: 7 | X10: 20.7917 | Y10: 51 | Z10: 53.7917 | AB10: 7 | AC10: 37.6957 | AD10: 61 | AE10: 96.2174 | AG10: 7 | AH10: 43.3158 | AI10: 55 | AJ10: 103.9474 | AL10: 7 | AM10: 36.6471 | AN10: 43 | AO10: 75.2941 | AQ10: 7 | AR10: 30.95 | AS10: 49 | AT10: 96.85 | AV10: 7 | AW10: 45.3333 | AX10: 37 | AY10: 98 | BA10: 7 | BB10: 48.8 | BC10: 52 | BD10: 104.15 | BF10: 7 | BG10: 46.6667 | BH10: 41 | BI10: 84.1111 | BK10: 7 | BL10: 42.6667 | BM10: 53 | BN10: 106.1333 | BP10: 7 | BQ10: 29 | BR10: 64 | BS10: 94.6087 | BU10: 7 | BV10: 36.1818 | BW10: 53 | BX10: 103.6364 | BZ10: 7 | CA10: 38.9474 | CB10: 53 | CC10: 90.6316 | CE10: 7 | CF10: 43.5714 | CG10: 50 | CH10: 104.4762 | CJ10: 7 | CK10: 15.8947 | CL10: 62 | CM10: 59.3684 | CO10: 7 | CP10: 36.5789 | CQ10: 59 | CR10: 97.3684 | CT10: 7 | CU10: 14.6875 | CV10: 49 | CW10: 57.875 | CY10: 7 | CZ10: 35.9333 | DA10: 44 | DB10: 82.8667 | DD10: 7 | DE10: 30.9333 | DF10: 46 | DG10: 74.4667 | DI10: 7 | DJ10: 47.8333 | DK10: 42 | DL10: 99.3333 | DN10: 7 | DO10: 69.875 | DP10: 53 | DQ10: 101.3125 | DS10: 7 | DT10: 24.9474 | DU10: 56 | DV10: 72.7368
B11: 8 | C11: 74.5729 | D11: 37 | E11: 106.9688 | H11: 8 | I11: 48.0625 | J11: 43 | K11: 92.5625 | M11: 7 | N11: 37.9 | O11: 50 | P11: 98 | R11: 7 | S11: 42.7368 | T11: 49 | U11: 100.9474 | W11: 8 | X11: 21.5 | Y11: 52 | Z11: 54.375 | AB11: 8 | AC11: 38.5652 | AD11: 62 | AE11: 95.4348 | AG11: 8 | AH11: 44.9474 | AI11: 56 | AJ11: 103.9474 | AL11: 8 | AM11: 38.8235 | AN11: 44 | AO11: 73.3529 | AQ11: 8 | AR11: 36.7 | AS11: 50 | AT11: 95.4 | AV11: 8 | AW11: 47.7333 | AX11: 38 | AY11: 98.2667 | BA11: 8 | BB11: 48.1 | BC11: 53 | BD11: 102.6 | BF11: 8 | BG11: 50.2222 | BH11: 42 | BI11: 83.4444 | BK11: 8 | BL11: 47.0667 | BM11: 54 | BN11: 106.3333 | BP11: 8 | BQ11: 30 | BR11: 65 | BS11: 93.3043 | BU11: 8 | BV11: 38.4091 | BW11: 54 | BX11: 104.7273 | BZ11: 8 | CA11: 41.2105 | CB11: 54 | CC11: 92.0526 | CE11: 8 | CF11: 46.0952 | CG11: 51 | CH11: 104.619 | CJ11: 8 | CK11: 18.4211 | CL11: 63 | CM11: 59.2105 | CO11: 8 | CP11: 41.1053 | CQ11: 60 | CR11: 99 | CT11: 8 | CU11: 16.1875 | CV11: 50 | CW11: 53.5625 | CY11: 8 | CZ11: 39 | DA11: 45 | DB11: 79.8667 | DD11: 8 | DE11: 31.6 | DF11: 47 | DG11: 74.2 | DI11: 8 | DJ11: 50.4167 | DK11: 43 | DL11: 99 | DN11: 8 | DO11: 77.0625 | DP11: 54 | DQ11: 101.625 | DS11: 8 | DT11: 25.5789 | DU11: 57 | DV11: 71.8947
B12: 9 | C12: 78.1771 | D12: 38 | E12: 108.0729 | H12: 9 | I12: 51.5625 | J12: 44 | K12: 88.75 | M12: 8 | N12: 42.4 | O12: 51 | P12: 101.6 | R12: 8 | S12: 43.4737 | T12: 50 | U12: 101.6316 | W12: 9 | X12: 22.375 | Y12: 53 | Z12: 54.0833 | AB12: 9 | AC12: 40 | AD12: 63 | AE12: 94.1739 | AG12: 9 | AH12: 46.8421 | AI12: 57 | AJ12: 104.2632 | AL12: 9 | AM12: 42.5294 | AN12: 45 | AO12: 71.4118 | AQ12: 9 | AR12: 42.9 | AS12: 51 | AT12: 95.5 | AV12: 9 | AW12: 50.9333 | AX12: 39 | AY12: 97.9333 | BA12: 9 | BB12: 49.9 | BC12: 54 | BD12: 98.2 | BF12: 9 | BG12: 52.7778 | BH12: 43 | BI12: 80.5 | BK12: 9 | BL12: 49.8667 | BM12: 55 | BN12: 105.8 | BP12: 9 | BQ12: 31.3043 | BR12: 66 | BS12: 91.0435 | BU12: 9 | BV12: 41 | BW12: 55 | BX12: 105.2273 | BZ12: 9 | CA12: 43.1053 | CB12: 55 | CC12: 94.7368 | CE12: 9 | CF12: 48.7143 | CG12: 52 | CH12: 104.8571 | CJ12: 9 | CK12: 21.4211 | CL12: 64 | CM12: 59.1053 | CO12: 9 | CP12: 46.3684 | CQ12: 61 | CR12: 100.6842 | CT12: 9 | CU12: 19.0625 | CV12: 51 | CW12: 52.375 | CY12: 9 | CZ12: 42.7333 | DA12: 46 | DB12: 75.2667 | DD12: 9 | DE12: 32 | DF12: 48 | DG12: 73.5333 | DI12: 9 | DJ12: 55.6667 | DK12: 44 | DL12: 96.3333 | DN12: 9 | DO12: 81.6875 | DP12: 55 | DQ12: 103.9375 | DS12: 9 | DT12: 26.1053 | DU12: 58 | DV12: 69.9474
B13: 10 | C13: 81.25 | D13: 39 | E13: 107.4688 | H13: 10 | I13: 55.125 | J13: 45 | K13: 86.1875 | M13: 9 | N13: 48.7 | O13: 52 | P13: 102.45 | R13: 9 | S13: 43.8947 | T13: 51 | U13: 103.1053 | W13: 10 | X13: 23.4167 | Y13: 54 | Z13: 53.3333 | AB13: 10 | AC13: 41.6957 | AD13: 64 | AE13: 92.913 | AG13: 10 | AH13: 48.1579 | AI13: 58 | AJ13: 103.8421 | AL13: 10 | AM13: 47.3529 | AN13: 46 | AO13: 68.5882 | AQ13: 10 | AR13: 45.2 | AS13: 52 | AT13: 95.35 | AV13: 10 | AW13: 54.6 | AX13: 40 | AY13: 96.2 | BA13: 10 | BB13: 52.35 | BC13: 55 | BD13: 93.55 | BF13: 10 | BG13: 56.6111 | BH13: 44 | BI13: 76.5 | BK13: 10 | BL13: 51.9333 | BM13: 56 | BN13: 104.2 | BP13: 10 | BQ13: 32.1304 | BR13: 67 | BS13: 88.7826 | BU13: 10 | BV13: 44.0909 | BW13: 56 | BX13: 104.7273 | BZ13: 10 | CA13: 44.6316 | CB13: 56 | CC13: 95.4211 | CE13: 10 | CF13: 51.4286 | CG13: 53 | CH13: 104.381 | CJ13: 10 | CK13: 24.6842 | CL13: 65 | CM13: 59 | CO13: 10 | CP13: 55.2632 | CQ13: 62 | CR13: 99.6316 | CT13: 10 | CU13: 21.6875 | CV13: 52 | CW13: 53.1875 | CY13: 10 | CZ13: 46.5333 | DA13: 47 | DB13: 72.9333 | DD13: 10 | DE13: 32.6 | DF13: 49 | DG13: 72.4667 | DI13: 10 | DJ13: 62.5833 | DK13: 45 | DL13: 94.5 | DN13: 10 | DO13: 83.4375 | DP13: 56 | DQ13: 106 | DS13: 10 | DT13: 26.5789 | DU13: 59 | DV13: 67.7895
B14: 11 | C14: 82.9167 | D14: 40 | E14: 105.9583 | H14: 11 | I14: 57.3125 | J14: 46 | K14: 83.5625 | M14: 10 | N14: 55.7 | O14: 53 | P14: 102.35 | R14: 10 | S14: 44.7895 | T14: 52 | U14: 104.6842 | W14: 11 | X14: 24.25 | Y14: 55 | Z14: 52.5417 | AB14: 11 | AC14: 43.4348 | AD14: 65 | AE14: 91.4783 | AG14: 11 | AH14: 49.5789 | AI14: 59 | AJ14: 102.6842 | AL14: 11 | AM14: 51.8235 | AN14: 47 | AO14: 65.1176 | AQ14: 11 | AR14: 46 | AS14: 53 | AT14: 93.45 | AV14: 11 | AW14: 57.2667 | AX14: 41 | AY14: 91.2 | BA14: 11 | BB14: 56 | BC14: 56 | BD14: 89.45 | BF14: 11 | BG14: 62.6667 | BH14: 45 | BI14: 73.1667 | BK14: 11 | BL14: 58.1333 | BM14: 57 | BN14: 103.6667 | BP14: 11 | BQ14: 33.1739 | BR14: 68 | BS14: 87.087 | BU14: 11 | BV14: 47.2727 | BW14: 57 | BX14: 104.1364 | BZ14: 11 | CA14: 47.2632 | CB14: 57 | CC14: 96.9474 | CE14: 11 | CF14: 54.619 | CG14: 54 | CH14: 104 | CJ14: 11 | CK14: 27.4211 | CL14: 66 | CM14: 59.3684 | CO14: 11 | CP14: 67.5789 | CQ14: 63 | CR14: 96.2632 | CT14: 11 | CU14: 24.5 | CV14: 53 | CW14: 53.4375 | CY14: 11 | CZ14: 48.8667 | DA14: 48 | DB14: 72.3333 | DD14: 11 | DE14: 34 | DF14: 50 | DG14: 71.8667 | DI14: 11 | DJ14: 66.8333 | DK14: 46 | DL14: 94.6667 | DN14: 11 | DO14: 84.1875 | DP14: 57 | DQ14: 106.3125 | DS14: 11 | DT14: 27.3684 | DU14: 60 | DV14: 65.2632
B15: 12 | C15: 84.4896 | D15: 41 | E15: 104.3958 | H15: 12 | I15: 59.1875 | J15: 47 | K15: 80.5 | M15: 11 | N15: 62.05 | O15: 54 | P15: 101.6 | R15: 11 | S15: 46.9474 | T15: 53 | U15: 107.2632 | W15: 12 | X15: 25.4583 | Y15: 56 | Z15: 51.625 | AB15: 12 | AC15: 44.3043 | AD15: 66 | AE15: 90.1304 | AG15: 12 | AH15: 50.7368 | AI15: 60 | AJ15: 101.7368 | AL15: 12 | AM15: 53.8824 | AN15: 48 | AO15: 62.1765 | AQ15: 12 | AR15: 46.6 | AS15: 54 | AT15: 91.2 | AV15: 12 | AW15: 59.3333 | AX15: 42 | AY15: 83.6 | BA15: 12 | BB15: 60.7 | BC15: 57 | BD15: 87.8 | BF15: 12 | BG15: 69.1111 | BH15: 46 | BI15: 70.3889 | BK15: 12 | BL15: 66.2667 | BM15: 58 | BN15: 104.2667 | BP15: 12 | BQ15: 34.6087 | BR15: 69 | BS15: 85.6957 | BU15: 12 | BV15: 49.6818 | BW15: 58 | BX15: 102.9545 | BZ15: 12 | CA15: 51.4737 | CB15: 58 | CC15: 98.8947 | CE15: 12 | CF15: 57.8571 | CG15: 55 | CH15: 104.1429 | CJ15: 12 | CK15: 29.8421 | CL15: 67 | CM15: 59.8421 | CO15: 12 | CP15: 78.0526 | CQ15: 64 | CR15: 92.8421 | CT15: 12 | CU15: 26 | CV15: 54 | CW15: 54.5 | CY15: 12 | CZ15: 50.1333 | DA15: 49 | DB15: 70.1333 | DD15: 12 | DE15: 36.8667 | DF15: 51 | DG15: 71.1333 | DI15: 12 | DJ15: 68.25 | DK15: 47 | DL15: 96.75 | DN15: 12 | DO15: 85.3125 | DP15: 58 | DQ15: 105.375 | DS15: 12 | DT15: 28.4211 | DU15: 61 | DV15: 62.6316
... B31: 28 | C31: 105.6875 | D31: 57 | E31: 72.1562 | H31: 28 | I31: 98.6875 | J31: 63 | K31: 44.9375 | M31: 27 | N31: 91.65 | O31: 70 | P31: 61 | R31: 27 | S31: 86.1579 | T31: 69 | U31: 49.7368 | W31: 28 | X31: 41.9583 | Y31: 72 | Z31: 29.125 | AB31: 28 | AC31: 75.4348 | AD31: 82 | AE31: 67 | AG31: 28 | AH31: 75.1053 | AI31: 76 | AJ31: 69.2632 | AL31: 28 | AM31: 78.5882 | AN31: 64 | AO31: 31.8235 | AQ31: 28 | AR31: 82.65 | AS31: 70 | AT31: 62.3 | AV31: 28 | AW31: 105.8667 | AX31: 58 | AY31: 36.5333 | BA31: 28 | BB31: 104.4 | BC31: 73 | BD31: 70.25 | BF31: 28 | BG31: 88.6111 | BH31: 62 | BI31: 42.7778 | BK31: 28 | BL31: 97.0667 | BM31: 74 | BN31: 71.6 | BP31: 28 | BQ31: 65.7826 | BR31: 85 | BS31: 57.6522 | BU31: 28 | BV31: 83.1364 | BW31: 74 | BX31: 66.7273 | BZ31: 28 | CA31: 96.3158 | CB31: 74 | CC31: 62.1053 | CE31: 28 | CF31: 90.4286 | CG31: 71 | CH31: 72.0476 | CJ31: 28 | CK31: 57.2105 | CL31: 83 | CM31: 41.5263 | CO31: 28 | CP31: 96.0526 | CQ31: 80 | CR31: 60.5789 | CT31: 28 | CU31: 52.375 | CV31: 70 | CW31: 50.625 | CY31: 28 | CZ31: 83.5333 | DA31: 65 | DB31: 24.2 | DD31: 28 | DE31: 76.5333 | DF31: 67 | DG31: 46.2667 | DI31: 28 | DJ31: 87.25 | DK31: 63 | DL31: 39 | DN31: 28 | DO31: 101.5625 | DP31: 74 | DQ31: 85.125 | DS31: 28 | DT31: 52.5789 | DU31: 77 | DV31: 41.7895
C32: =AVERAGE(C3:C31) -> 86.406621 | D32: =AVERAGE(D3:D31) -> 43 | E32: =AVERAGE(E3:E31) -> 97.58009 | H32: 29 | I32: 95.875 | J32: 64 | K32: 41.375 | M32: 28 | N32: 91.9 | O32: 71 | P32: 57.3 | R32: 28 | S32: 84.9474 | T32: 70 | U32: 47.7895 | W32: 29 | X32: 43 | Y32: 73 | Z32: 28.875 | AB32: 29 | AC32: 76.2609 | AD32: 83 | AE32: 64.5652 | AG32: 29 | AH32: 79.1053 | AI32: 77 | AJ32: 67.3158 | AL32: 29 | AM32: 78.1765 | AN32: 65 | AO32: 30.2353 | AQ32: 29 | AR32: 86.25 | AS32: 71 | AT32: 63.65 | AV32: 29 | AW32: 104.6 | AX32: 59 | AY32: 33.7333 | BA32: 29 | BB32: 103.55 | BC32: 74 | BD32: 69 | BF32: 29 | BG32: 87.4444 | BH32: 63 | BI32: 39.5 | BK32: 29 | BL32: 95.2 | BM32: 75 | BN32: 69.8667 | BP32: 29 | BQ32: 67.4348 | BR32: 86 | BS32: 58.3478 | BU32: 29 | BV32: 85.5 | BW32: 75 | BX32: 65.0455 | BZ32: 29 | CA32: 97.8421 | CB32: 75 | CC32: 58.5263 | CE32: 29 | CF32: 90.9048 | CG32: 72 | CH32: 69.6667 | CJ32: 29 | CK32: 58.8947 | CL32: 84 | CM32: 41 | CO32: 29 | CP32: 96.3158 | CQ32: 81 | CR32: 59 | CT32: 29 | CU32: 54.9375 | CV32: 71 | CW32: 47.6875 | CY32: 29 | CZ32: 83.8 | DA32: 66 | DB32: 22.9333 | DD32: 29 | DE32: 78.4 | DF32: 68 | DG32: 43.2 | DI32: 29 | DJ32: 87.8333 | DK32: 64 | DL32: 36.4167 | DN32: 29 | DO32: 101.3125 | DP32: 75 | DQ32: 86.6875 | DS32: 29 | DT32: 56.6316 | DU32: 78 | DV32: 40.9474
H33: 30 | I33: 93.375 | J33: 65 | K33: 38.8125 | M33: 29 | N33: 90.6 | O33: 72 | P33: 55.7 | R33: 29 | S33: 84.0526 | T33: 71 | U33: 45.7895 | W33: 30 | X33: 43.7083 | Y33: 74 | Z33: 28.625 | AB33: 30 | AC33: 77.6087 | AD33: 84 | AE33: 61.8261 | AG33: 30 | AH33: 83.8947 | AI33: 78 | AJ33: 62.6316 | AL33: 30 | AM33: 77.7059 | AN33: 66 | AO33: 29 | AQ33: 30 | AR33: 88.35 | AS33: 72 | AT33: 64.2 | BA33: 30 | BB33: 101.65 | BC33: 75 | BD33: 66.85 | BF33: 30 | BG33: 86.4444 | BH33: 64 | BI33: 38.1667 | BK33: 30 | BL33: 93.4 | BM33: 76 | BN33: 68.3333 | BP33: 30 | BQ33: 69.2174 | BR33: 87 | BS33: 58.1304 | BU33: 30 | BV33: 86.8636 | BW33: 76 | BX33: 62.5 | BZ33: 30 | CA33: 99.4737 | CB33: 76 | CC33: 54.1053 | CE33: 30 | CF33: 91 | CG33: 73 | CH33: 68.4286 | CJ33: 30 | CK33: 60.2105 | CL33: 85 | CM33: 40.0526 | CO33: 30 | CP33: 98.6842 | CQ33: 82 | CR33: 56.9474 | CT33: 30 | CU33: 59 | CV33: 72 | CW33: 44.5 | CY33: 30 | CZ33: 81.0667 | DA33: 67 | DB33: 21.2667 | DD33: 30 | DE33: 77.7333 | DF33: 69 | DG33: 39.1333 | DI33: 30 | DJ33: 91.4167 | DK33: 65 | DL33: 33.9167 | DN33: 30 | DO33: 100.75 | DP33: 76 | DQ33: 86 | DS33: 30 | DT33: 59.8947 | DU33: 79 | DV33: 39.6842
A34: Entire Columella | H34: 31 | I34: 92.6875 | J34: 66 | K34: 38.1875 | M34: 30 | N34: 88.95 | O34: 73 | P34: 52.6 | R34: 30 | S34: 84.2632 | T34: 72 | U34: 44.9474 | W34: 31 | X34: 43.9167 | Y34: 75 | Z34: 28.375 | AB34: 31 | AC34: 79.6522 | AD34: 85 | AE34: 59.3478 | AG34: 31 | AH34: 87.9474 | AI34: 79 | AJ34: 59.5789 | AL34: 31 | AM34: 76.8235 | AN34: 67 | AO34: 28.5882 | AQ34: 31 | AR34: 89.85 | AS34: 73 | AT34: 62.45 | AV34: entire 1613 | BA34: 31 | BB34: 99.25 | BC34: 76 | BD34: 63.85 | BF34: 31 | BG34: 86.2222 | BH34: 65 | BI34: 37.2778 | BK34: 31 | BL34: 93 | BM34: 77 | BN34: 65.7333 | BP34: 31 | BQ34: 71.4348 | BR34: 88 | BS34: 56.8261 | BU34: 31 | BV34: 87.6364 | BW34: 77 | BX34: 59.7727 | BZ34: 31 | CA34: 102.5789 | CB34: 77 | CC34: 52.0526 | CE34: 31 | CF34: 91.6667 | CG34: 74 | CH34: 67.0476 | CJ34: 31 | CK34: 61.4211 | CL34: 86 | CM34: 39.3158 | CO34: 31 | CP34: 99.7368 | CQ34: 83 | CR34: 55.0526 | CT34: 31 | CU34: 62.75 | CV34: 73 | CW34: 41.25 | CY34: 31 | CZ34: 79.7333 | DA34: 68 | DB34: 20.2667 | DD34: 31 | DE34: 75.9333 | DF34: 70 | DG34: 36.9333 | DI34: 31 | DJ34: 96.3333 | DK34: 66 | DL34: 30.5 | DN34: 31 | DO34: 99.5 | DP34: 77 | DQ34: 81.25 | DS34: 31 | DT34: 63.3158 | DU34: 80 | DV34: 37.7368
B35: Id | H35: 32 | I35: 92.5 | J35: 67 | K35: 36.6875 | M35: 31 | N35: 89.15 | O35: 74 | P35: 48.6 | R35: 31 | S35: 84.7368 | T35: 73 | U35: 45.0526 | W35: 32 | X35: 43.7917 | Y35: 76 | Z35: 27.625 | AB35: 32 | AC35: 83.3478 | AD35: 86 | AE35: 57.6522 | AG35: 32 | AH35: 92 | AI35: 80 | AJ35: 57.3684 | AL35: 32 | AM35: 76.1176 | AN35: 68 | AO35: 27.5294 | AQ35: 32 | AR35: 89.8 | AS35: 74 | AT35: 58.7 | AV35: 0 | AW35: 45.5254 | BA35: 32 | BB35: 97.1 | BC35: 77 | BD35: 61.6 | BF35: 32 | BG35: 86.2778 | BH35: 66 | BI35: 35.9444 | BK35: 32 | BL35: 94.9333 | BM35: 78 | BN35: 63.0667 | BP35: 32 | BQ35: 73.913 | BR35: 89 | BS35: 55 | BU35: 32 | BV35: 88.7273 | BW35: 78 | BX35: 57.8182 | BZ35: 32 | CA35: 105.8947 | CB35: 78 | CC35: 51.2632 | CE35: 32 | CF35: 93.5238 | CG35: 75 | CH35: 65 | CJ35: 32 | CK35: 62.2632 | CL35: 87 | CM35: 38.7895 | CO35: 32 | CP35: 99.2105 | CQ35: 84 | CR35: 53.9474 | CT35: 32 | CU35: 65.125 | CV35: 74 | CW35: 38.3125 | CY35: 32 | CZ35: 79 | DA35: 69 | DB35: 19 | DD35: 32 | DE35: 74.6667 | DF35: 71 | DG35: 35.5333 | DI35: 32 | DJ35: 98.9167 | DK35: 67 | DL35: 29.5833 | DN35: 32 | DO35: 98.75 | DP35: 78 | DQ35: 80.4375 | DS35: 32 | DT35: 66.4211 | DU35: 81 | DV35: 35.5263
A36: 1603 | B36: 0 | C36: 21.32 | H36: 33 | I36: 92.8125 | J36: 68 | K36: 34.9375 | M36: 32 | N36: 88.2 | O36: 75 | P36: 44.7 | R36: 32 | S36: 84.4737 | T36: 74 | U36: 45.1579 | W36: 33 | X36: 45 | Y36: 77 | Z36: 26 | AB36: 33 | AC36: 87.7391 | AD36: 87 | AE36: 56.7826 | AG36: 33 | AH36: 94.4211 | AI36: 81 | AJ36: 55 | AL36: 33 | AM36: 75.7647 | AN36: 69 | AO36: 26.3529 | AQ36: 33 | AR36: 89.3 | AS36: 75 | AT36: 53.85 | AV36: 1 | AW36: 49.1695 | BA36: 33 | BB36: 95.35 | BC36: 78 | BD36: 59.3 | BF36: 33 | BG36: 86.8889 | BH36: 67 | BI36: 33.3889 | BK36: 33 | BL36: 98.3333 | BM36: 79 | BN36: 60.1333 | BP36: 33 | BQ36: 76.087 | BR36: 90 | BS36: 53.2174 | BU36: 33 | BV36: 90.3182 | BW36: 79 | BX36: 56.5909 | BZ36: 33 | CA36: 107.8421 | CB36: 79 | CC36: 49.8947 | CE36: 33 | CF36: 95.1905 | CG36: 76 | CH36: 61.9048 | CJ36: 33 | CK36: 62.2632 | CL36: 88 | CM36: 38.3684 | CO36: 33 | CP36: 98.4211 | CQ36: 85 | CR36: 53.7368 | CT36: 33 | CU36: 65.875 | CV36: 75 | CW36: 35.5 | CY36: 33 | CZ36: 76.8667 | DA36: 70 | DB36: 17.6 | DD36: 33 | DE36: 74.4667 | DF36: 72 | DG36: 34.3333 | DI36: 33 | DJ36: 101.3333 | DK36: 68 | DL36: 28.5 | DN36: 33 | DO36: 98.4375 | DP36: 79 | DQ36: 83.1875 | DS36: 33 | DT36: 68.2105 | DU36: 82 | DV36: 33.4737
B37: 1 | C37: 21.48 | H37: 34 | I37: 92.375 | J37: 69 | K37: 33.6875 | M37: 33 | N37: 87.05 | O37: 76 | P37: 41.2 | R37: 33 | S37: 85.0526 | T37: 75 | U37: 44.7895 | W37: 34 | X37: 47.8333 | Y37: 78 | Z37: 24 | AB37: 34 | AC37: 91.3043 | AD37: 88 | AE37: 56.0435 | AG37: 34 | AH37: 95.7895 | AI37: 82 | AJ37: 51.6842 | AL37: 34 | AM37: 75.2353 | AN37: 70 | AO37: 25.2941 | AQ37: 34 | AR37: 89.15 | AS37: 76 | AT37: 48.9 | AV37: 2 | AW37: 53.7627 | BA37: 34 | BB37: 94.6 | BC37: 79 | BD37: 56.4 | BK37: 34 | BL37: 101.1333 | BM37: 80 | BN37: 55.8667 | BP37: 34 | BQ37: 78.7391 | BR37: 91 | BS37: 50.6522 | BU37: 34 | BV37: 91.5 | BW37: 80 | BX37: 55.3636 | BZ37: 34 | CA37: 106.8947 | CB37: 80 | CC37: 49.4737 | CE37: 34 | CF37: 95.4286 | CG37: 77 | CH37: 58.3333 | CJ37: 34 | CK37: 62.1053 | CL37: 89 | CM37: 37.8421 | CO37: 34 | CP37: 97.2632 | CQ37: 86 | CR37: 54.2632 | CT37: 34 | CU37: 65.4375 | CV37: 76 | CW37: 31.8125 | CY37: 34 | CZ37: 73.8 | DA37: 71 | DB37: 16.2 | DD37: 34 | DE37: 73.8667 | DF37: 73 | DG37: 33.7333 | DI37: 34 | DJ37: 101.4167 | DK37: 69 | DL37: 28.4167 | DN37: 34 | DO37: 99.125 | DP37: 80 | DQ37: 86.5625 | DS37: 34 | DT37: 69.7895 | DU37: 83 | DV37: 31.5263
B38: 2 | C38: 22.44 | M38: 34 | N38: 87.5 | O38: 77 | P38: 38 | R38: 34 | S38: 86.4737 | T38: 76 | U38: 43.7895 | W38: 35 | X38: 51.4583 | Y38: 79 | Z38: 22.125 | AB38: 35 | AC38: 93.3043 | AD38: 89 | AE38: 55 | AG38: 35 | AH38: 98.2105 | AI38: 83 | AJ38: 48.4737 | AL38: 35 | AM38: 75.3529 | AN38: 71 | AO38: 24.7647 | AQ38: 35 | AR38: 88.2 | AS38: 77 | AT38: 45.05 | AV38: 3 | AW38: 59.7458 | BA38: 35 | BB38: 95.5 | BC38: 80 | BD38: 53.4 | BF38: entire 1615 | BK38: 35 | BL38: 104.0667 | BM38: 81 | BN38: 52.9333 | BP38: 35 | BQ38: 80.8696 | BR38: 92 | BS38: 48.6087 | BU38: 35 | BV38: 92.5455 | BW38: 81 | BX38: 54.1364 | BZ38: 35 | CA38: 104.3158 | CB38: 81 | CC38: 49.5789 | CE38: 35 | CF38: 97.2857 | CG38: 78 | CH38: 54.9048 | CJ38: 35 | CK38: 62 | CL38: 90 | CM38: 37 | CO38: 35 | CP38: 96.0526 | CQ38: 87 | CR38: 53.9474 | CT38: 35 | CU38: 65.875 | CV38: 77 | CW38: 28.625 | CY38: 35 | CZ38: 74.6 | DA38: 72 | DB38: 15.4667 | DD38: 35 | DE38: 72.6 | DF38: 74 | DG38: 32.9333 | DN38: 35 | DO38: 100.9375 | DP38: 81 | DQ38: 84.6875 | DS38: 35 | DT38: 72.2105 | DU38: 84 | DV38: 29.5263
B39: 3 | C39: 23.2 | M39: 35 | N39: 90.5 | O39: 78 | P39: 34.75 | R39: 35 | S39: 88.8421 | T39: 77 | U39: 41.6316 | W39: 36 | X39: 55.875 | Y39: 80 | Z39: 21.375 | AB39: 36 | AC39: 94.2609 | AD39: 90 | AE39: 53.6087 | AG39: 36 | AH39: 101.0526 | AI39: 84 | AJ39: 45.4211 | AQ39: 36 | AR39: 88.25 | AS39: 78 | AT39: 40.15 | AV39: 4 | AW39: 64.9153 | BA39: 36 | BB39: 96.85 | BC39: 81 | BD39: 50.2 | BF39: 0 | BG39: 60.2931 | BK39: 36 | BL39: 104.7333 | BM39: 82 | BN39: 49.7333 | BP39: 36 | BQ39: 83.3043 | BR39: 93 | BS39: 46.2609 | BU39: 36 | BV39: 93.7273 | BW39: 82 | BX39: 51.8182 | BZ39: 36 | CA39: 101.9474 | CB39: 82 | CC39: 49.2632 | CE39: 36 | CF39: 99.1429 | CG39: 79 | CH39: 50.9048 | CJ39: 36 | CK39: 61.6316 | CL39: 91 | CM39: 36.2105 | CO39: 36 | CP39: 95.7895 | CQ39: 88 | CR39: 53.6316 | CT39: 36 | CU39: 66.8125 | CV39: 78 | CW39: 26 | CY39: 36 | CZ39: 80.9333 | DA39: 73 | DB39: 14.8667 | DD39: 36 | DE39: 71.6667 | DF39: 75 | DG39: 32 | DI39: entire 1626 | DN39: 36 | DO39: 102.6875 | DP39: 82 | DQ39: 81.8125 | DS39: 36 | DT39: 75.2105 | DU39: 85 | DV39: 28.3684
B40: 4 | C40: 24.2 | I40: Entire | M40: 36 | N40: 98.35 | O40: 79 | P40: 32.6 | R40: 36 | S40: 91.8947 | T40: 78 | U40: 39.3684 | W40: 37 | X40: 60.5 | Y40: 81 | Z40: 21.0417 | AB40: 37 | AC40: 94.6087 | AD40: 91 | AE40: 51.5217 | AG40: 37 | AH40: 101.9474 | AI40: 85 | AJ40: 44.5263 | AL40: entire | AQ40: 37 | AR40: 90.75 | AS40: 79 | AT40: 34.5 | AV40: 5 | AW40: 67.983 | BA40: 37 | BB40: 97.25 | BC40: 82 | BD40: 47.6 | BF40: 1 | BG40: 64.3448 | BK40: 37 | BL40: 104.1333 | BM40: 83 | BN40: 46.2 | BP40: 37 | BQ40: 85.3913 | BR40: 94 | BS40: 44.3043 | BU40: 37 | BV40: 96.2273 | BW40: 83 | BX40: 47.3182 | BZ40: 37 | CA40: 100.4211 | CB40: 83 | CC40: 47.7368 | CE40: 37 | CF40: 99.619 | CG40: 80 | CH40: 47.8095 | CJ40: 37 | CK40: 61.2632 | CL40: 92 | CM40: 35.3684 | CO40: 37 | CP40: 96.1053 | CQ40: 89 | CR40: 53.6842 | CT40: 37 | CU40: 68.1875 | CV40: 79 | CW40: 22.875 | DD40: 37 | DE40: 72.5333 | DF40: 76 | DG40: 30.9333 | DI40: 0 | DJ40: 47.4839 | DN40: 37 | DO40: 104 | DP40: 83 | DQ40: 81.125 | DS40: 37 | DT40: 77.8421 | DU40: 86 | DV40: 27.0526
B41: 5 | C41: 25.16 | I41: 1604 | J41: Pixels | M41: 37 | N41: 107.1 | O41: 80 | P41: 31.6 | R41: 37 | S41: 94.7368 | T41: 79 | U41: 37.8421 | W41: 38 | X41: 64.0417 | Y41: 82 | Z41: 20.625 | AB41: 38 | AC41: 94.913 | AD41: 92 | AE41: 49.2174 | AG41: 38 | AH41: 102.5789 | AI41: 86 | AJ41: 41.6316 | AL41: 1610 | AQ41: 38 | AR41: 93.65 | AS41: 80 | AT41: 31 | AV41: 6 | AW41: 70.6271 | BA41: 38 | BB41: 97.3 | BC41: 83 | BD41: 44.8 | BF41: 2 | BG41: 68.5862 | BK41: 38 | BL41: 103.8 | BM41: 84 | BN41: 43.3333 | BP41: 38 | BQ41: 87.1304 | BR41: 95 | BS41: 41.8261 | BU41: 38 | BV41: 99.6818 | BW41: 84 | BX41: 42.4091 | BZ41: 38 | CA41: 99.2632 | CB41: 84 | CC41: 45.6842 | CE41: 38 | CF41: 100.0952 | CG41: 81 | CH41: 44.4286 | CJ41: 38 | CK41: 61.3158 | CL41: 93 | CM41: 34.3158 | CO41: 38 | CP41: 96.4211 | CQ41: 90 | CR41: 52.8421 | CT41: 38 | CU41: 69.875 | CV41: 80 | CW41: 20.4375 | CY41: entire 1624 | DD41: 38 | DE41: 73.8667 | DF41: 77 | DG41: 29.8 | DI41: 1 | DJ41: 48.7097 | DN41: 38 | DO41: 105.1875 | DP41: 84 | DQ41: 77.125 | DS41: 38 | DT41: 78.3158 | DU41: 87 | DV41: 26.0526
B42: 6 | C42: 26.64 | J42: 0 | K42: 54.4151 | M42: 38 | N42: 112.6 | O42: 81 | P42: 30.35 | R42: 38 | S42: 98.1579 | T42: 80 | U42: 35.7895 | W42: 39 | X42: 66.2083 | Y42: 83 | Z42: 20.125 | AB42: 39 | AC42: 96.087 | AD42: 93 | AE42: 46.6957 | AG42: 39 | AH42: 103.8421 | AI42: 87 | AJ42: 38.9474 | AL42: 0 | AM42: 36.0556 | AQ42: 39 | AR42: 97.05 | AS42: 81 | AT42: 28.3 | AV42: 7 | AW42: 72.5932 | BA42: 39 | BB42: 98.35 | BC42: 84 | BD42: 40.45 | BF42: 3 | BG42: 71.7069 | BK42: 39 | BL42: 104.5333 | BM42: 85 | BN42: 40.6 | BP42: 39 | BQ42: 89.3043 | BR42: 96 | BS42: 40.3913 | BU42: 39 | BV42: 102 | BW42: 85 | BX42: 38.8182 | BZ42: 39 | CA42: 99.1579 | CB42: 85 | CC42: 43.6316 | CE42: 39 | CF42: 100.619 | CG42: 82 | CH42: 40.7619 | CJ42: 39 | CK42: 61.4211 | CL42: 94 | CM42: 33.1053 | CO42: 39 | CP42: 94.2632 | CQ42: 91 | CR42: 50.6842 | CT42: 39 | CU42: 72.1875 | CV42: 81 | CW42: 18.0625 | CY42: 0 | CZ42: 28.6923 | DI42: 2 | DJ42: 50.4839 | DN42: 39 | DO42: 106.9375 | DP42: 85 | DQ42: 71.5 | DS42: 39 | DT42: 78.9474 | DU42: 88 | DV42: 25.2105
B43: 7 | C43: 29.2 | J43: 1 | K43: 58.8491 | M43: 39 | N43: 113.1 | O43: 82 | P43: 29 | R43: 39 | S43: 102.2632 | T43: 81 | U43: 33.6842 | W43: 40 | X43: 66.375 | Y43: 84 | Z43: 19.5417 | AB43: 40 | AC43: 97 | AD43: 94 | AE43: 44.2174 | AG43: 40 | AH43: 105.0526 | AI43: 88 | AJ43: 37.1579 | AL43: 1 | AM43: 41.2963 | AQ43: 40 | AR43: 104 | AS43: 82 | AT43: 25.9 | AV43: 8 | AW43: 77.6949 | BA43: 40 | BB43: 99.75 | BC43: 85 | BD43: 35.65 | BF43: 4 | BG43: 74.2931 | BK43: 40 | BL43: 104.5333 | BM43: 86 | BN43: 37.9333 | BP43: 40 | BQ43: 90.8696 | BR43: 97 | BS43: 38.6087 | BU43: 40 | BV43: 103.0909 | BW43: 86 | BX43: 36.5 | BZ43: 40 | CA43: 100.3158 | CB43: 86 | CC43: 41.8947 | CE43: 40 | CF43: 100.5714 | CG43: 83 | CH43: 37.6667 | CJ43: 40 | CK43: 61.3684 | CL43: 95 | CM43: 31.7895 | CO43: 40 | CP43: 92.4211 | CQ43: 92 | CR43: 48.8421 | CT43: 40 | CU43: 75.8125 | CV43: 82 | CW43: 15.375 | CY43: 1 | CZ43: 32.4038 | DD43: entire 1625 | DI43: 3 | DJ43: 52.3548 | DN43: 40 | DO43: 108.875 | DP43: 86 | DQ43: 68.5625 | DS43: 40 | DT43: 80.0526 | DU43: 89 | DV43: 24.6842
B44: 8 | C44: 30.56 | J44: 2 | K44: 65.4906 | M44: 40 | N44: 109.3 | O44: 83 | P44: 28.65 | R44: 40 | S44: 105.5789 | T44: 82 | U44: 31.6842 | W44: 41 | X44: 65.2917 | Y44: 85 | Z44: 18.875 | AB44: 41 | AC44: 97.3043 | AD44: 95 | AE44: 41.2174 | AG44: 41 | AH44: 105.1053 | AI44: 89 | AJ44: 34.2105 | AL44: 2 | AM44: 49.3704 | AQ44: 41 | AR44: 112.2 | AS44: 83 | AT44: 23.6 | AV44: 9 | AW44: 82.5085 | BA44: 41 | BB44: 100.95 | BC44: 86 | BD44: 31.55 | BF44: 5 | BG44: 77.4483 | BK44: 41 | BL44: 105 | BM44: 87 | BN44: 35.1333 | BP44: 41 | BQ44: 91.4348 | BR44: 98 | BS44: 36.4783 | BU44: 41 | BV44: 103.5909 | BW44: 87 | BX44: 34.4091 | BZ44: 41 | CA44: 102.6316 | CB44: 87 | CC44: 40.4211 | CE44: 41 | CF44: 100.8571 | CG44: 84 | CH44: 34.7619 | CJ44: 41 | CK44: 61.4737 | CL44: 96 | CM44: 31 | CO44: 41 | CP44: 93.6842 | CQ44: 93 | CR44: 47.8421 | CT44: 41 | CU44: 77.875 | CV44: 83 | CW44: 13.5625 | CY44: 2 | CZ44: 37.3462 | DD44: 0 | DE44: 44.6944 | DI44: 4 | DJ44: 55.5806 | DN44: 41 | DO44: 110.9375 | DP44: 87 | DQ44: 62.3125 | DS44: 41 | DT44: 80.7895 | DU44: 90 | DV44: 23.9474
B45: 9 | C45: 31.12 | J45: 3 | K45: 72.6226 | M45: 41 | N45: 104.2 | O45: 84 | P45: 28.1 | R45: 41 | S45: 107.4211 | T45: 83 | U45: 30.3684 | W45: 42 | X45: 63 | Y45: 86 | Z45: 18.125 | AB45: 42 | AC45: 97.9565 | AD45: 96 | AE45: 38.3043 | AG45: 42 | AH45: 104.7368 | AI45: 90 | AJ45: 31.1053 | AL45: 3 | AM45: 55.0741 | AV45: 10 | AW45: 84.2881 | BA45: 42 | BB45: 102.45 | BC45: 87 | BD45: 28.75 | BF45: 6 | BG45: 81.6552 | BK45: 42 | BL45: 105.7333 | BM45: 88 | BN45: 32.4667 | BP45: 42 | BQ45: 92.3913 | BR45: 99 | BS45: 34 | BU45: 42 | BV45: 104.2273 | BW45: 88 | BX45: 32.2273 | BZ45: 42 | CA45: 106.2632 | CB45: 88 | CC45: 38.8421 | CE45: 42 | CF45: 101.4286 | CG45: 85 | CH45: 32.5238 | CJ45: 42 | CK45: 62.2632 | CL45: 97 | CM45: 30.1579 | CO45: 42 | CP45: 97.8947 | CQ45: 94 | CR45: 46.0526 | CY45: 3 | CZ45: 42.2692 | DD45: 1 | DE45: 46.2778 | DI45: 5 | DJ45: 60.4194 | DN45: 42 | DO45: 111.125 | DP45: 88 | DQ45: 53.875 | DS45: 42 | DT45: 80.0526 | DU45: 91 | DV45: 23.6316
B46: 10 | C46: 32.12 | J46: 4 | K46: 80.3396 | M46: 42 | N46: 100 | O46: 85 | P46: 26.55 | W46: 43 | X46: 60.6667 | Y46: 87 | Z46: 17.9583 | AB46: 43 | AC46: 98.6957 | AD46: 97 | AE46: 36.2174 | AG46: 43 | AH46: 104.2632 | AI46: 91 | AJ46: 28.8947 | AL46: 4 | AM46: 58.5926 | AQ46: entire 1611 | AV46: 11 | AW46: 87.6441 | BA46: 43 | BB46: 103.15 | BC46: 88 | BD46: 26.25 | BF46: 7 | BG46: 85.2069 | BK46: 43 | BL46: 105.8667 | BM46: 89 | BN46: 31.5333 | BP46: 43 | BQ46: 93.1304 | BR46: 100 | BS46: 32.3913 | BU46: 43 | BV46: 104.6818 | BW46: 89 | BX46: 30.8636 | BZ46: 43 | CA46: 111.3158 | CB46: 89 | CC46: 37.5789 | CJ46: 43 | CK46: 63.0526 | CL46: 98 | CM46: 29.2632 | CO46: 43 | CP46: 101.1053 | CQ46: 95 | CR46: 43 | CT46: entire 1623 | CY46: 4 | CZ46: 47.9038 | DD46: 2 | DE46: 48.8472 | DI46: 6 | DJ46: 66.7258 | DN46: 43 | DO46: 110.625 | DP46: 89 | DQ46: 37.3125 | DS46: 43 | DT46: 78.1579 | DU46: 92 | DV46: 23.3684
B47: 11 | C47: 33.12 | J47: 5 | K47: 85.8868 | AB47: 44 | AC47: 99.6957 | AD47: 98 | AE47: 34.4783 | AG47: 44 | AH47: 103.8947 | AI47: 92 | AJ47: 27.5789 | AL47: 5 | AM47: 64.9074 | AQ47: 0 | AR47: 39.8846 | AV47: 12 | AW47: 92.4915 | BA47: 44 | BB47: 105.25 | BC47: 89 | BD47: 25 | BF47: 8 | BG47: 88.4828 | BK47: 44 | BL47: 104.8667 | BM47: 90 | BN47: 31.0667 | BP47: 44 | BQ47: 92.3478 | BR47: 101 | BS47: 30.6957 | BU47: 44 | BV47: 104.7273 | BW47: 90 | BX47: 30.0909 | BZ47: 44 | CA47: 115.3158 | CB47: 90 | CC47: 35.7368 | CE47: entire 1620 | CJ47: 44 | CK47: 64.0526 | CL47: 99 | CM47: 29.1053 | CO47: 44 | CP47: 102.5263 | CQ47: 96 | CR47: 39.7895 | CT47: 0 | CU47: 24.3654 | CY47: 5 | CZ47: 54.25 | DD47: 3 | DE47: 52.125 | DI47: 7 | DJ47: 72.8871 | DN47: 44 | DO47: 109.5 | DP47: 90 | DQ47: 26.3125 | DS47: 44 | DT47: 77.7895 | DU47: 93 | DV47: 22.9474
B48: 12 | C48: 35.2 | J48: 6 | K48: 87.4906 | M48: Entire | R48: entire | W48: entire | AB48: 45 | AC48: 100.5652 | AD48: 99 | AE48: 33 | AG48: 45 | AH48: 103.4211 | AI48: 93 | AJ48: 26.2632 | AL48: 6 | AM48: 73.0741 | AQ48: 1 | AR48: 43.25 | AV48: 13 | AW48: 96.9153 | BF48: 9 | BG48: 92.0862 | BK48: 45 | BL48: 104.8667 | BM48: 91 | BN48: 30.3333 | BP48: 45 | BQ48: 93.6087 | BR48: 102 | BS48: 28.3043 | BU48: 45 | BV48: 104.2727 | BW48: 91 | BX48: 29.6818 | BZ48: 45 | CA48: 117.1053 | CB48: 91 | CC48: 33.1579 | CE48: 0 | CF48: 53.2462 | CJ48: 45 | CK48: 64.7895 | CL48: 100 | CM48: 28.2632 | CO48: 45 | CP48: 102.1053 | CQ48: 97 | CR48: 37.2105 | CT48: 1 | CU48: 25.7885 | CY48: 6 | CZ48: 59.8077 | DD48: 4 | DE48: 55.3472 | DI48: 8 | DJ48: 78.1774 | DN48: 45 | DO48: 108.6875 | DP48: 91 | DQ48: 23.5625 | DS48: 45 | DT48: 77.4211 | DU48: 94 | DV48: 22.7895
B49: 13 | C49: 38.24 | J49: 7 | K49: 88.5849 | M49: 1605 | R49: 1606 | W49: 1607 | AB49: 46 | AC49: 100.6957 | AD49: 100 | AE49: 31.7391 | AG49: 46 | AH49: 103.1579 | AI49: 94 | AJ49: 25.2632 | AL49: 7 | AM49: 76.8333 | AQ49: 2 | AR49: 48.75 | AV49: 14 | AW49: 100.5424 | BA49: entire 1614 | BF49: 10 | BG49: 93.9483 | BP49: 46 | BQ49: 93.7826 | BR49: 103 | BS49: 25.7391 | CE49: 1 | CF49: 53.9538 | CJ49: 46 | CK49: 65.5789 | CL49: 101 | CM49: 27.5263 | CO49: 46 | CP49: 100.8947 | CQ49: 98 | CR49: 35.6842 | CT49: 2 | CU49: 28.6346 | CY49: 7 | CZ49: 60.5577 | DD49: 5 | DE49: 57.9028 | DI49: 9 | DJ49: 82.2258 | DS49: 46 | DT49: 76.4737 | DU49: 95 | DV49: 22.1053
B50: 14 | C50: 42.2 | J50: 8 | K50: 92.283 | M50: pixels | R50: pixels | W50: 0 | X50: 56.2742 | AB50: 47 | AC50: 100.3478 | AD50: 101 | AE50: 30.8261 | AG50: 47 | AH50: 103.3158 | AI50: 95 | AJ50: 24.2105 | AL50: 8 | AM50: 77.0556 | AQ50: 3 | AR50: 54.5385 | AV50: 15 | AW50: 102.983 | BF50: 11 | BG50: 94.8966 | BK50: entire 1616 | BP50: 47 | BQ50: 94.3043 | BR50: 104 | BS50: 23.9565 | BU50: entire 1618 | BZ50: entire 1619 | CE50: 2 | CF50: 54.6154 | CJ50: 47 | CK50: 65.7368 | CL50: 102 | CM50: 27.0526 | CO50: 47 | CP50: 98.6842 | CQ50: 99 | CR50: 34.1579 | CT50: 3 | CU50: 32.8462 | CY50: 8 | CZ50: 61 | DD50: 6 | DE50: 60.7222 | DI50: 10 | DJ50: 85.7097 | DN50: entire 1627 | DS50: 47 | DT50: 76.2105 | DU50: 96 | DV50: 22.1053
B51: 15 | C51: 46.04 | J51: 9 | K51: 96.9811 | M51: 0 | N51: 65.2069 | R51: 0 | S51: 58.4512 | W51: 1 | X51: 59.5323 | AB51: 48 | AC51: 100.0435 | AD51: 102 | AE51: 30.3478 | AL51: 9 | AM51: 76.4259 | AQ51: 4 | AR51: 60.1154 | AV51: 16 | AW51: 104.8814 | BA51: 0 | BB51: 56.8676 | BF51: 12 | BG51: 96.5345 | BK51: 0 | BL51: 53.4828 | BP51: 48 | BQ51: 95.3043 | BR51: 105 | BS51: 22.913 | BU51: 0 | BV51: 52.9091 | BZ51: 0 | CA51: 58.2154 | CE51: 3 | CF51: 56.1538 | CJ51: 48 | CK51: 66.0526 | CL51: 103 | CM51: 26.4737 | CO51: 48 | CP51: 97.3684 | CQ51: 100 | CR51: 32.5789 | CT51: 4 | CU51: 37.0192 | CY51: 9 | CZ51: 66.2115 | DD51: 7 | DE51: 64.2361 | DI51: 11 | DJ51: 88.9032 | DN51: 0 | DO51: 49.56 | DS51: 48 | DT51: 76.7368 | DU51: 97 | DV51: 21.8421
B52: 16 | C52: 50.12 | J52: 10 | K52: 100.2076 | M52: 1 | N52: 66.4828 | R52: 1 | S52: 59.5 | W52: 2 | X52: 64.8064 | AB52: 49 | AC52: 99.5217 | AD52: 103 | AE52: 29.6087 | AG52: entire | AL52: 10 | AM52: 76.4259 | AQ52: 5 | AR52: 66.1346 | AV52: 17 | AW52: 105.8136 | BA52: 1 | BB52: 60.4853 | BF52: 13 | BG52: 98.8103 | BK52: 1 | BL52: 55.6207 | BP52: 49 | BQ52: 94.2609 | BR52: 106 | BS52: 22.4348 | BU52: 1 | BV52: 55.197 | BZ52: 1 | CA52: 59.1077 | CE52: 4 | CF52: 58.7077 | CJ52: 49 | CK52: 66 | CL52: 104 | CM52: 25.6842 | CO52: 49 | CP52: 97.4211 | CQ52: 101 | CR52: 30 | CT52: 5 | CU52: 40.8462 | CY52: 10 | CZ52: 71.7692 | DD52: 8 | DE52: 68.25 | DI52: 12 | DJ52: 90.129 | DN52: 1 | DO52: 51.4
B53: 17 | C53: 53.52 | J53: 11 | K53: 103.7547 | M53: 2 | N53: 69 | R53: 2 | S53: 60.4268 | W53: 3 | X53: 70.2903 | AB53: 50 | AC53: 99.0435 | AD53: 104 | AE53: 28.6957 | AG53: 1609 | AL53: 11 | AM53: 78.537 | AQ53: 6 | AR53: 71.8269 | AV53: 18 | AW53: 105.678 | BA53: 2 | BB53: 64.7353 | BF53: 14 | BG53: 100.8448 | BK53: 2 | BL53: 58.3793 | BP53: 50 | BQ53: 94.6957 | BR53: 107 | BS53: 21.7826 | BU53: 2 | BV53: 58.2727 | BZ53: 2 | CA53: 61.6 | CE53: 5 | CF53: 61.2462 | CJ53: 50 | CK53: 65.7895 | CL53: 105 | CM53: 25.0526 | CO53: 50 | CP53: 97.7368 | CQ53: 102 | CR53: 27.7895 | CT53: 6 | CU53: 45.5962 | CY53: 11 | CZ53: 75.6538 | DD53: 9 | DE53: 72.3889 | DI53: 13 | DJ53: 90.4839 | DN53: 2 | DO53: 54.2667 | DS53: entire 1628
B54: 18 | C54: 57 | J54: 12 | K54: 108.8868 | M54: 3 | N54: 72.0172 | R54: 3 | S54: 62.0732 | W54: 4 | X54: 74.7903 | AB54: 51 | AC54: 98.4783 | AD54: 105 | AE54: 27.5652 | AG54: 0 | AH54: 39.7818 | AL54: 12 | AM54: 82.6111 | AQ54: 7 | AR54: 76.3846 | AV54: 19 | AW54: 105.9492 | BA54: 3 | BB54: 67.7059 | BF54: 15 | BG54: 102.7241 | BK54: 3 | BL54: 61.1034 | BP54: 51 | BQ54: 95.8261 | BR54: 108 | BS54: 21.2174 | BU54: 3 | BV54: 61.4394 | BZ54: 3 | CA54: 64.5077 | CE54: 6 | CF54: 63.4615 | CJ54: 51 | CK54: 65.3684 | CL54: 106 | CM54: 24.3158 | CO54: 51 | CP54: 96.1579 | CQ54: 103 | CR54: 25.7368 | CT54: 7 | CU54: 52.2115 | CY54: 12 | CZ54: 78.5385 | DD54: 10 | DE54: 76.3889 | DI54: 14 | DJ54: 93.2903 | DN54: 3 | DO54: 57.0133 | DS54: 0 | DT54: 34.2812
B55: 19 | C55: 60.8 | J55: 13 | K55: 114.0755 | M55: 4 | N55: 74.9655 | R55: 4 | S55: 66.6585 | W55: 5 | X55: 78.3064 | AB55: 52 | AC55: 97.8261 | AD55: 106 | AE55: 26.087 | AG55: 1 | AH55: 41.4 | AL55: 13 | AM55: 88.8889 | AQ55: 8 | AR55: 81.5 | AV55: 20 | AW55: 106.0339 | BA55: 4 | BB55: 68.7353 | BF55: 16 | BG55: 104.3103 | BK55: 4 | BL55: 63.6724 | BP55: 52 | BQ55: 96.5652 | BR55: 109 | BS55: 20.6522 | BU55: 4 | BV55: 64.5909 | BZ55: 4 | CA55: 67.3231 | CE55: 7 | CF55: 66.6154 | CJ55: 52 | CK55: 65.1579 | CL55: 107 | CM55: 23.6842 | CT55: 8 | CU55: 59.9808 | CY55: 13 | CZ55: 83.5385 | DD55: 11 | DE55: 79.75 | DI55: 15 | DJ55: 95.7581 | DN55: 4 | DO55: 59.6667 | DS55: 1 | DT55: 35.1458
...

Sheet Con_Analysis
B1: Bottom Cells | D1: R:L (SUMS) | E1: Bottom Cells | G1: Bottom Cells (stdev.s | I1: Entire Columella
A2: ID | B2: SUM RIGHT | C2: SUM LEFT | D2: Ratio | E2: AVG RIGHT | F2: AVG LEFT | G2: STD RIGHT | H2: STD LEFT | I2: SUM | J2: AVG | K2: STD
A3: 1603 | B3: =SUM('Raw Values_Con'!C3:C31) -> 2505.792 | C3: =SUM('Raw Values_Con'!E3:E31) -> 2829.8226 | D3: =B3/C3 -> 0.88549438 | E3: =AVERAGE('Raw Values_Con'!C3:C31) -> 86.406621 | F3: =AVERAGE('Raw Values_Con'!E3:E31) -> 97.58009 | G3: =_xlfn.STDEV.S('Raw Values_Con'!C3:C31) -> 15.227781 | H3: =_xlfn.STDEV.S('Raw Values_Con'!E3:E31) -> 11.260755 | I3: =SUM('Raw Values_Con'!$C$36:$C$133) -> 6562 | J3: =AVERAGE('Raw Values_Con'!$C$36:$C$133) -> 66.959184 | K3: =_xlfn.STDEV.S('Raw Values_Con'!$C$36:$C$133) -> 26.377027
A4: 1604 | B4: =SUM('Raw Values_Con'!I3:I37) -> 2488.75 | C4: =SUM('Raw Values_Con'!K3:K37) -> 2400.25 | D4: =B4/C4 -> 1.0368712 | E4: =AVERAGE('Raw Values_Con'!I3:I37) -> 71.107143 | F4: =AVERAGE('Raw Values_Con'!K3:K37) -> 68.578571 | G4: =_xlfn.STDEV.S('Raw Values_Con'!I3:I37) -> 23.901027 | H4: =_xlfn.STDEV.S('Raw Values_Con'!K3:K37) -> 21.463629 | I4: =SUM('Raw Values_Con'!K42:K89) -> 4750.5473 | J4: =AVERAGE('Raw Values_Con'!K42:K89) -> 98.969735 | K4: =_xlfn.STDEV.S('Raw Values_Con'!K42:K89) -> 19.831355
A5: 1605 | B5: =SUM('Raw Values_Con'!N4:N46) -> 3262.6 | C5: =SUM('Raw Values_Con'!P4:P46) -> 3019 | D5: =B5/C5 -> 1.080689 | E5: =AVERAGE('Raw Values_Con'!$N$4:$N$46) -> 75.874419 | F5: =AVERAGE('Raw Values_Con'!$P$4:$P$46) -> 70.209302 | G5: =_xlfn.STDEV.S('Raw Values_Con'!$N$4:$N$46) -> 26.691381 | H5: =_xlfn.STDEV.S('Raw Values_Con'!P4:P46) -> 26.415571 | I5: =SUM('Raw Values_Con'!$N$51:$N$100) -> 4902.1898 | J5: =AVERAGE('Raw Values_Con'!$N$51:$N$100) -> 98.043796 | K5: =_xlfn.STDEV.S('Raw Values_Con'!$N$51:$N$100) -> 16.887505
A6: 1606 | B6: =SUM('Raw Values_Con'!$S$4:$S$45) -> 2836.842 | C6: =SUM('Raw Values_Con'!$U$4:$U$45) -> 3125.3161 | D6: =B6/C6 -> 0.90769762 | E6: =AVERAGE('Raw Values_Con'!$S$4:$S$45) -> 67.543857 | F6: =AVERAGE('Raw Values_Con'!$U$4:$U$45) -> 74.412288 | G6: =_xlfn.STDEV.S('Raw Values_Con'!$S$4:$S$45) -> 22.677701 | H6: =_xlfn.STDEV.S('Raw Values_Con'!$U$4:$U$45) -> 28.477754 | I6: =SUM('Raw Values_Con'!$S$51:$S$104) -> 5073.9267 | J6: =AVERAGE('Raw Values_Con'!$S$51:$S$104) -> 93.961606 | K6: =_xlfn.STDEV.S('Raw Values_Con'!$S$51:$S$104) -> 18.294716
A7: 1607 | B7: =SUM('Raw Values_Con'!$X$3:$X$46) -> 1631.4999 | C7: =SUM('Raw Values_Con'!$Z$3:$Z$46) -> 1694.2084 | D7: =B7/C7 -> 0.96298655 | E7: =AVERAGE('Raw Values_Con'!$X$3:$X$46) -> 37.079543 | F7: =AVERAGE('Raw Values_Con'!$Z$3:$Z$46) -> 38.504736 | G7: =_xlfn.STDEV.S('Raw Values_Con'!$X$3:$X$46) -> 15.397958 | H7: =_xlfn.STDEV.S('Raw Values_Con'!$Z$3:$Z$46) -> 13.762075 | I7: =SUM('Raw Values_Con'!$X$50:$X$91) -> 3652.516 | J7: =AVERAGE('Raw Values_Con'!$X$50:$X$91) -> 86.964667 | K7: =_xlfn.STDEV.S('Raw Values_Con'!$X$50:$X$91) -> 18.374921
A8: 1608 | B8: =SUM('Raw Values_Con'!$AC$3:$AC$56) -> 3764.6522 | C8: =SUM('Raw Values_Con'!$AE$3:$AE$56) -> 3549.4348 | D8: =B8/C8 -> 1.0606343 | E8: =AVERAGE('Raw Values_Con'!$AC$3:$AC$56) -> 69.715781 | F8: =AVERAGE('Raw Values_Con'!$AE$3:$AE$56) -> 65.730274 | G8: =_xlfn.STDEV.S('Raw Values_Con'!$AC$3:$AC$56) -> 25.726206 | H8: =_xlfn.STDEV.S('Raw Values_Con'!$AE$3:$AE$56) -> 24.452745 | I8: =SUM('Raw Values_Con'!$AC$60:$AC$109) -> 5198.1488 | J8: =AVERAGE('Raw Values_Con'!$AC$60:$AC$109) -> 103.96298 | K8: =_xlfn.STDEV.S('Raw Values_Con'!$AC$60:$AC$109) -> 12.804467
A9: 1609 | B9: =SUM('Raw Values_Con'!$AH$3:$AH$50) -> 3366.7895 | C9: =SUM('Raw Values_Con'!$AJ$3:$AJ$50) -> 3585.6319 | D9: =B9/C9 -> 0.93896685 | E9: =AVERAGE('Raw Values_Con'!$AH$3:$AH$50) -> 70.141448 | F9: =AVERAGE('Raw Values_Con'!$AJ$3:$AJ$50) -> 74.700665 | G9: =_xlfn.STDEV.S('Raw Values_Con'!$AH$3:$AH$50) -> 25.947538 | H9: =_xlfn.STDEV.S('Raw Values_Con'!$AJ$3:$AJ$50) -> 28.913872 | I9: =SUM('Raw Values_Con'!$AH$54:$AH$113) -> 4893.6361 | J9: =AVERAGE('Raw Values_Con'!$AH$54:$AH$113) -> 81.560602 | K9: =_xlfn.STDEV.S('Raw Values_Con'!$AH$54:$AH$113) -> 22.208464
A10: 1610 | B10: =SUM('Raw Values_Con'!$AM$3:$AM$38) -> 2092.4115 | C10: =SUM('Raw Values_Con'!$AO$3:$AO$38) -> 1906.4703 | D10: =B10/C10 -> 1.0975317 | E10: =AVERAGE('Raw Values_Con'!$AM$3:$AM$38) -> 58.122542 | F10: =AVERAGE('Raw Values_Con'!$AO$3:$AO$38) -> 52.957508 | G10: =_xlfn.STDEV.S('Raw Values_Con'!$AM$3:$AM$38) -> 18.709253 | H10: =_xlfn.STDEV.S('Raw Values_Con'!$AO$3:$AO$38) -> 18.702556 | I10: =SUM('Raw Values_Con'!$AM$42:$AM$91) -> 4177.037 | J10: =AVERAGE('Raw Values_Con'!$AM$42:$AM$91) -> 83.54074 | K10: =_xlfn.STDEV.S('Raw Values_Con'!$AM$42:$AM$91) -> 18.999226
A11: 1611 | B11: =SUM('Raw Values_Con'!$AR$3:$AR$44) -> 2606.95 | C11: =SUM('Raw Values_Con'!$AT$3:$AT$44) -> 3014.55 | D11: =B11/C11 -> 0.86478911 | E11: =AVERAGE('Raw Values_Con'!$AR$3:$AR$44) -> 62.070238 | F11: =AVERAGE('Raw Values_Con'!$AT$3:$AT$44) -> 71.775 | G11: =_xlfn.STDEV.S('Raw Values_Con'!$AR$3:$AR$44) -> 26.336928 | H11: =_xlfn.STDEV.S('Raw Values_Con'!$AT$3:$AT$44) -> 26.860072 | I11: =SUM('Raw Values_Con'!$AR$47:$AR$86) -> 3247.346 | J11: =AVERAGE('Raw Values_Con'!$AR$47:$AR$86) -> 81.18365 | K11: =_xlfn.STDEV.S('Raw Values_Con'!$AR$47:$AR$86) -> 24.350239
A12: 1613 | B12: =SUM('Raw Values_Con'!$AW$3:$AW$32) -> 2093.3999 | C12: =SUM('Raw Values_Con'!$AY$3:$AY$32) -> 2174.5333 | D12: =B12/C12 -> 0.96268928 | E12: =AVERAGE('Raw Values_Con'!$AW$3:$AW$32) -> 69.779997 | F12: =AVERAGE('Raw Values_Con'!$AY$3:$AY$32) -> 72.484443 | G12: =_xlfn.STDEV.S('Raw Values_Con'!$AW$3:$AW$32) -> 27.48889 | H12: =_xlfn.STDEV.S('Raw Values_Con'!$AY$3:$AY$32) -> 24.880642 | I12: =SUM('Raw Values_Con'!$AW$35:$AW$84) -> 4390.1019 | J12: =AVERAGE('Raw Values_Con'!$AW$35:$AW$84) -> 87.802038 | K12: =_xlfn.STDEV.S('Raw Values_Con'!$AW$35:$AW$84) -> 19.725697
A13: 1614 | B13: =SUM('Raw Values_Con'!$BB$3:$BB$47) -> 3414.95 | C13: =SUM('Raw Values_Con'!$BD$3:$BD$47) -> 3453 | D13: =B13/C13 -> 0.9889806 | E13: =AVERAGE('Raw Values_Con'!$BB$3:$BB$47) -> 75.887778 | F13: =AVERAGE('Raw Values_Con'!$BD$3:$BD$47) -> 76.733333 | G13: =_xlfn.STDEV.S('Raw Values_Con'!$BB$3:$BB$47) -> 24.288257 | H13: =_xlfn.STDEV.S('Raw Values_Con'!$BD$3:$BD$47) -> 25.311637 | I13: =SUM('Raw Values_Con'!$BB$51:$BB$107) -> 5376.9708 | J13: =AVERAGE('Raw Values_Con'!$BB$51:$BB$107) -> 94.332821 | K13: =_xlfn.STDEV.S('Raw Values_Con'!$BB$51:$BB$107) -> 16.900578
A14: 1615 | B14: =SUM('Raw Values_Con'!$BG$3:$BG$36) -> 2357.9998 | C14: =SUM('Raw Values_Con'!$BI$3:$BI$36) -> 2152.5001 | D14: =B14/C14 -> 1.0954702 | E14: =AVERAGE('Raw Values_Con'!$BG$3:$BG$36) -> 69.352935 | F14: =AVERAGE('Raw Values_Con'!$BI$3:$BI$36) -> 63.308826 | G14: =_xlfn.STDEV.S('Raw Values_Con'!$BG$3:$BG$36) -> 22.217583 | H14: =_xlfn.STDEV.S('Raw Values_Con'!$BI$3:$BI$36) -> 17.771419 | I14: =SUM('Raw Values_Con'!$BG$39:$BG$86) -> 4342.0172 | J14: =AVERAGE('Raw Values_Con'!$BG$39:$BG$86) -> 90.458692 | K14: =_xlfn.STDEV.S('Raw Values_Con'!$BG$39:$BG$86) -> 16.201504
A15: 1616 | B15: =SUM('Raw Values_Con'!$BL$3:$BL$48) -> 3614.0665 | C15: =SUM('Raw Values_Con'!$BN$3:$BN$48) -> 3581.9331 | D15: =B15/C15 -> 1.008971 | E15: =AVERAGE('Raw Values_Con'!$BL$3:$BL$48) -> 78.566663 | F15: =AVERAGE('Raw Values_Con'!$BN$3:$BN$48) -> 77.868111 | G15: =_xlfn.STDEV.S('Raw Values_Con'!$BL$3:$BL$48) -> 25.271524 | H15: =_xlfn.STDEV.S('Raw Values_Con'!$BN$3:$BN$48) -> 26.563353 | I15: =SUM('Raw Values_Con'!$BL$51:$BL$107) -> 5354.207 | J15: =AVERAGE('Raw Values_Con'!$BL$51:$BL$107) -> 93.933456 | K15: =_xlfn.STDEV.S('Raw Values_Con'!$BL$51:$BL$107) -> 20.382912
A16: 1617 | B16: =SUM('Raw Values_Con'!$BQ$3:$BQ$59) -> 3678.3912 | C16: =SUM('Raw Values_Con'!$BS$3:$BS$59) -> 3382.2607 | D16: =B16/C16 -> 1.087554 | E16: =AVERAGE('Raw Values_Con'!$BQ$3:$BQ$59) -> 64.533179 | F16: =AVERAGE('Raw Values_Con'!$BS$3:$BS$59) -> 59.337907 | G16: =_xlfn.STDEV.S('Raw Values_Con'!$BQ$3:$BQ$59) -> 26.36896 | H16: =_xlfn.STDEV.S('Raw Values_Con'!$BS$3:$BS$59) -> 27.407008 | I16: =SUM('Raw Values_Con'!$BQ$63:$BQ$133) -> 6603.9159 | J16: =AVERAGE('Raw Values_Con'!$BQ$63:$BQ$133) -> 93.0129 | K16: =_xlfn.STDEV.S('Raw Values_Con'!$BQ$63:$BQ$133) -> 18.731331
A17: 1618 | B17: =SUM('Raw Values_Con'!$BV$3:$BV$48) -> 3170.6818 | C17: =SUM('Raw Values_Con'!$BX$3:$BX$48) -> 3459.5457 | D17: =B17/C17 -> 0.91650236 | E17: =AVERAGE('Raw Values_Con'!$BV$3:$BV$48) -> 68.927865 | F17: =AVERAGE('Raw Values_Con'!$BX$3:$BX$48) -> 75.207515 | G17: =_xlfn.STDEV.S('Raw Values_Con'!$BV$3:$BV$48) -> 25.753241 | H17: =_xlfn.STDEV.S('Raw Values_Con'!$BX$3:$BX$48) -> 25.879433 | I17: =SUM('Raw Values_Con'!$BV$51:$BV$109) -> 5479.97 | J17: =AVERAGE('Raw Values_Con'!$BV$51:$BV$109) -> 92.880847 | K17: =_xlfn.STDEV.S('Raw Values_Con'!$BV$51:$BV$109) -> 20.938404
A18: 1619 | B18: =SUM('Raw Values_Con'!$CA$3:$CA$48) -> 3519.053 | C18: =SUM('Raw Values_Con'!$CC$3:$CC$48) -> 3478.4734 | D18: =B18/C18 -> 1.0116659 | E18: =AVERAGE('Raw Values_Con'!$CA$3:$CA$48) -> 76.501152 | F18: =AVERAGE('Raw Values_Con'!$CC$3:$CC$48) -> 75.618987 | G18: =_xlfn.STDEV.S('Raw Values_Con'!$CA$3:$CA$48) -> 28.469993 | H18: =_xlfn.STDEV.S('Raw Values_Con'!$CC$3:$CC$48) -> 25.744054 | I18: =SUM('Raw Values_Con'!$CA$51:$CA$116) -> 6504.9389 | J18: =AVERAGE('Raw Values_Con'!$CA$51:$CA$116) -> 98.55968 | K18: =_xlfn.STDEV.S('Raw Values_Con'!$CA$51:$CA$116) -> 19.607955
A19: 1620 | B19: =SUM('Raw Values_Con'!$CF$3:$CF$45) -> 3099.8569 | C19: =SUM('Raw Values_Con'!$CH$3:$CH$45) -> 3530.7621 | D19: =B19/C19 -> 0.87795689 | E19: =AVERAGE('Raw Values_Con'!$CF$3:$CF$45) -> 72.089695 | F19: =AVERAGE('Raw Values_Con'!$CH$3:$CH$45) -> 82.110747 | G19: =_xlfn.STDEV.S('Raw Values_Con'!$CF$3:$CF$45) -> 23.136205 | H19: =_xlfn.STDEV.S('Raw Values_Con'!$CH$3:$CH$45) -> 23.659024 | I19: =SUM('Raw Values_Con'!$CF$48:$CF$112) -> 5456.0616 | J19: =AVERAGE('Raw Values_Con'!$CF$48:$CF$112) -> 83.939409 | K19: =_xlfn.STDEV.S('Raw Values_Con'!$CF$48:$CF$112) -> 21.168919
A20: 1621 | B20: =SUM('Raw Values_Con'!$CK$3:$CK$57) -> 2647.3686 | C20: =SUM('Raw Values_Con'!$CM$3:$CM$57) -> 2413.4737 | D20: =B20/C20 -> 1.0969121 | E20: =AVERAGE('Raw Values_Con'!$CK$3:$CK$57) -> 48.133975 | F20: =AVERAGE('Raw Values_Con'!$CM$3:$CM$57) -> 43.88134 | G20: =_xlfn.STDEV.S('Raw Values_Con'!$CK$3:$CK$57) -> 19.325024 | H20: =_xlfn.STDEV.S('Raw Values_Con'!$CM$3:$CM$57) -> 13.855504 | I20: =SUM('Raw Values_Con'!$CK$60:$CK$132) -> 4943.3206 | J20: =AVERAGE('Raw Values_Con'!$CK$60:$CK$132) -> 67.716721 | K20: =_xlfn.STDEV.S('Raw Values_Con'!$CK$60:$CK$132) -> 17.856813
A21: 1622 | B21: =SUM('Raw Values_Con'!$CP$3:$CP$54) -> 4198.8948 | C21: =SUM('Raw Values_Con'!$CR$3:$CR$54) -> 3476.0002 | D21: =B21/C21 -> 1.2079674 | E21: =AVERAGE('Raw Values_Con'!$CP$3:$CP$54) -> 80.747977 | F21: =AVERAGE('Raw Values_Con'!$CR$3:$CR$54) -> 66.846158 | G21: =_xlfn.STDEV.S('Raw Values_Con'!$CP$3:$CP$54) -> 27.000914 | H21: =_xlfn.STDEV.S('Raw Values_Con'!$CR$3:$CR$54) -> 22.871467 | I21: =SUM('Raw Values_Con'!$CP$57:$CP$122) -> 5936.0464 | J21: =AVERAGE('Raw Values_Con'!$CP$57:$CP$122) -> 89.940097 | K21: =_xlfn.STDEV.S('Raw Values_Con'!$CP$57:$CP$122) -> 14.162055
A22: 1623 | B22: =SUM('Raw Values_Con'!$CU$3:$CU$44) -> 1665.3125 | C22: =SUM('Raw Values_Con'!$CW$3:$CW$44) -> 2112.0625 | D22: =B22/C22 -> 0.7884769 | E22: =AVERAGE('Raw Values_Con'!$CU$3:$CU$44) -> 39.650298 | F22: =AVERAGE('Raw Values_Con'!$CW$3:$CW$44) -> 50.287202 | G22: =_xlfn.STDEV.S('Raw Values_Con'!$CU$3:$CU$44) -> 21.754989 | H22: =_xlfn.STDEV.S('Raw Values_Con'!$CW$3:$CW$44) -> 17.074381 | I22: =SUM('Raw Values_Con'!$CU$47:$CU$98) -> 4030.7693 | J22: =AVERAGE('Raw Values_Con'!$CU$47:$CU$98) -> 77.514794 | K22: =_xlfn.STDEV.S('Raw Values_Con'!$CU$47:$CU$98) -> 27.706533
A23: 1624 | B23: =SUM('Raw Values_Con'!$CZ$3:$CZ$39) -> 2052.3998 | C23: =SUM('Raw Values_Con'!$DB$3:$DB$39) -> 1964.4001 | D23: =B23/C23 -> 1.0447972 | E23: =AVERAGE('Raw Values_Con'!$CZ$3:$CZ$39) -> 55.470265 | F23: =AVERAGE('Raw Values_Con'!$DB$3:$DB$39) -> 53.091895 | G23: =_xlfn.STDEV.S('Raw Values_Con'!$CZ$3:$CZ$39) -> 21.292026 | H23: =_xlfn.STDEV.S('Raw Values_Con'!$DB$3:$DB$39) -> 28.795123 | I23: =SUM('Raw Values_Con'!$CZ$42:$CZ$94) -> 3970.7883 | J23: =AVERAGE('Raw Values_Con'!$CZ$42:$CZ$94) -> 74.920534 | K23: =_xlfn.STDEV.S('Raw Values_Con'!$CZ$42:$CZ$94) -> 25.427006
A24: 1625 | B24: =SUM('Raw Values_Con'!$DE$3:$DE$41) -> 2138.5334 | C24: =SUM('Raw Values_Con'!$DG$3:$DG$41) -> 2277.4663 | D24: =B24/C24 -> 0.93899673 | E24: =AVERAGE('Raw Values_Con'!$DE$3:$DE$41) -> 54.83419 | F24: =AVERAGE('Raw Values_Con'!$DG$3:$DG$41) -> 58.396572 | G24: =_xlfn.STDEV.S('Raw Values_Con'!$DE$3:$DE$41) -> 19.57544 | H24: =_xlfn.STDEV.S('Raw Values_Con'!$DG$3:$DG$41) -> 16.294957 | I24: =SUM('Raw Values_Con'!$DE$44:$DE$105) -> 4935.7354 | J24: =AVERAGE('Raw Values_Con'!$DE$44:$DE$105) -> 79.608635 | K24: =_xlfn.STDEV.S('Raw Values_Con'!$DE$44:$DE$105) -> 20.587426
A25: 1626 | B25: =SUM('Raw Values_Con'!$DJ$3:$DJ$37) -> 2428.0834 | C25: =SUM('Raw Values_Con'!$DL$3:$DL$37) -> 2492.5834 | D25: =B25/C25 -> 0.97412323 | E25: =AVERAGE('Raw Values_Con'!$DJ$3:$DJ$37) -> 69.373811 | F25: =AVERAGE('Raw Values_Con'!$DL$3:$DL$37) -> 71.216669 | G25: =_xlfn.STDEV.S('Raw Values_Con'!$DJ$3:$DJ$37) -> 20.532807 | H25: =_xlfn.STDEV.S('Raw Values_Con'!$DL$3:$DL$37) -> 28.811429 | I25: =SUM('Raw Values_Con'!$DJ$40:$DJ$99) -> 5134.5482 | J25: =AVERAGE('Raw Values_Con'!$DJ$40:$DJ$99) -> 85.575803 | K25: =_xlfn.STDEV.S('Raw Values_Con'!$DJ$40:$DJ$99) -> 23.098863
A26: 1627 | B26: =SUM('Raw Values_Con'!$DO$3:$DO$48) -> 4050 | C26: =SUM('Raw Values_Con'!$DQ$3:$DQ$48) -> 3920.6875 | D26: =B26/C26 -> 1.0329821 | E26: =AVERAGE('Raw Values_Con'!$DO$3:$DO$48) -> 88.043478 | F26: =AVERAGE('Raw Values_Con'!$DQ$3:$DQ$48) -> 85.232337 | G26: =_xlfn.STDEV.S('Raw Values_Con'!$DO$3:$DO$48) -> 23.392517 | H26: =_xlfn.STDEV.S('Raw Values_Con'!$DQ$3:$DQ$48) -> 19.379998 | I26: =SUM('Raw Values_Con'!$DO$51:$DO$122) -> 6592.2534 | J26: =AVERAGE('Raw Values_Con'!$DO$51:$DO$122) -> 91.559075 | K26: =_xlfn.STDEV.S('Raw Values_Con'!$DO$51:$DO$122) -> 18.283989
A27: 1628 | B27: =SUM('Raw Values_Con'!$DT$3:$DT$51) -> 2400.4737 | C27: =SUM('Raw Values_Con'!$DV$3:$DV$51) -> 2298.9998 | D27: =B27/C27 -> 1.0441383 | E27: =AVERAGE('Raw Values_Con'!$DT$3:$DT$51) -> 48.989259 | F27: =AVERAGE('Raw Values_Con'!$DV$3:$DV$51) -> 46.918363 | G27: =_xlfn.STDEV.S('Raw Values_Con'!$DT$3:$DT$51) -> 22.094022 | H27: =_xlfn.STDEV.S('Raw Values_Con'!$DV$3:$DV$51) -> 18.789823 | I27: =SUM('Raw Values_Con'!$DT$54:$DT$104) -> 3518.7709 | J27: =AVERAGE('Raw Values_Con'!$DT$54:$DT$104) -> 68.995508 | K27: =_xlfn.STDEV.S('Raw Values_Con'!$DT$54:$DT$104) -> 17.801897
A29: Column AVGS | B29: =AVERAGE(B3:B27) -> 2843.4301 | C29: =AVERAGE(C3:C27) -> 2851.7346 | D29: =AVERAGE(D3:D27) -> 0.99655379 | E29: =AVERAGE(E3:E27) -> 66.357764 | F29: =AVERAGE(F3:F27) -> 66.919554 | G29: =AVERAGE(G3:G27) -> 23.143127 | H29: =AVERAGE(H3:H27) -> 22.535931 | I29: =AVERAGE(I3:I27) -> 5001.1105 | ... K29: =AVERAGE(K3:K27) -> 19.868392
B30: AVG SUM RIGHT | C30: AVG SUM LEFT | D30: AVG RATIO | E30: AVG OF AVG RIGHT | F30: AVG OF AVG LEFT | G30: AVG OF AVG LEFT

Sheet Raw Values_B3A
A1: Bottom | B1: 1630 | F1: Bottom | G1: 1631 | K1: Bottom | L1: 1633 | P1: Bottom | Q1: 1634 | U1: Bottom | V1: 1635 | Z1: Bottom | AA1: 1636 | AE1: Bottom | AF1: 1637 | AJ1: Bottom | AK1: 1638 | AO1: Bottom | AP1: 1639 | AT1: Bottom | AU1: 1642 | AY1: Bottom | AZ1: 1643 | BD1: Bottom | BE1: 1644 | BI1: Bottom | BJ1: 1645 | BN1: Bottom | BO1: 1646
A2: Pixels | B2: R | D2: L | F2: Pixels | G2: R | I2: L | K2: Pixels | L2: R | N2: L | P2: Pixels | Q2: R | S2: L | U2: Pixels | V2: R | X2: L | Z2: Pixels | AA2: R | AC2: L | AE2: Pixels | AF2: R | AH2: L | AJ2: Pixels | AK2: R | AM2: L | AO2: Pixels | AP2: R | AR2: L | AT2: Pixels | AU2: R | AW2: L | AY2: Pixels | AZ2: R | BB2: L | BD2: Pixels | BE2: R | BG2: L | BI2: Pixels | BJ2: R | BL2: L | BN2: Pixels | BO2: R | BQ2: L
A3: 0 | B3: 32.6111 | C3: 52 | D3: 94.2222 | F3: 0 | G3: 24.5833 | H3: 41 | I3: 105.8333 | K3: 0 | L3: 28.6 | M3: 36 | N3: 75.8 | P3: 0 | Q3: 27.0769 | R3: 35 | S3: 56.5385 | U3: 0 | V3: 28.625 | W3: 40 | X3: 65.4375 | Z3: 0 | AA3: 32.3913 | AB3: 29 | AC3: 79.1739 | AE3: 0 | AF3: 30.4615 | AG3: 31 | AH3: 75.6923 | AJ3: 0 | AK3: 32.8667 | AL3: 38 | AM3: 99.3333 | AO3: 0 | AP3: 24.3 | AQ3: 33 | AR3: 120.3 | AT3: 0 | AU3: 34.9444 | AV3: 46 | AW3: 93.7222 | AY3: 0 | AZ3: 28.2143 | BA3: 35 | BB3: 82.5714 | BD3: 0 | BE3: 30.8 | BF3: 30 | BG3: 75.2 | BI3: 0 | BJ3: 23.68 | BK3: 44 | BL3: 95.72 | BN3: 0 | BO3: 31 | BP3: 44 | BQ3: 101.9444
A4: 1 | B4: 33.6667 | C4: 53 | D4: 93.8333 | F4: 1 | G4: 25.3333 | H4: 42 | I4: 106.6667 | K4: 1 | L4: 30.2 | M4: 37 | N4: 76.4 | P4: 1 | Q4: 27.6154 | R4: 36 | S4: 56.6154 | U4: 1 | V4: 30 | W4: 41 | X4: 66.1875 | Z4: 1 | AA4: 40.6522 | AB4: 30 | AC4: 80.8696 | AE4: 1 | AF4: 31.5385 | AG4: 32 | AH4: 77.3077 | AJ4: 1 | AK4: 33.5333 | AL4: 39 | AM4: 101.4 | AO4: 1 | AP4: 26.4 | AQ4: 34 | AR4: 113.6 | AT4: 1 | AU4: 35.1667 | AV4: 47 | AW4: 93.5 | AY4: 1 | AZ4: 29.2857 | BA4: 36 | BB4: 82.5 | BD4: 1 | BE4: 32.1333 | BF4: 31 | BG4: 75.3333 | BI4: 1 | BJ4: 24.36 | BK4: 45 | BL4: 95.96 | BN4: 1 | BO4: 33.1111 | BP4: 45 | BQ4: 102.8889
