Workbook

Sheet raw_con
A1: Image_ID | C1: L | E1: R | G1: Image_ID | I1: L | K1: R | M1: Image_ID | O1: L | Q1: R | S1: Image_ID | U1: L | W1: R | Y1: Image_ID | AA1: L | AC1: R | AE1: Image_ID | AG1: L | AI1: R | AK1: Image_ID | AM1: L | AO1: R | AQ1: Image_ID | AS1: L | AU1: R | AW1: Image_ID | AY1: L | BA1: R | BC1: Image_ID | BE1: L | BG1: R | BI1: Image_ID | BK1: L | BM1: R | BO1: Image_ID | BQ1: L | BS1: R | BU1: Image_ID | BW1: L | BY1: R | CA1: Image_ID | CC1: L | CE1: R | CG1: Image_ID | CI1: L | CK1: R | CM1: Image_ID | CO1: L | CQ1: R | CS1: Image_ID | CU1: L | CW1: R | CY1: Image_ID | DA1: L | DC1: R | DE1: Image_ID | DG1: L | DI1: R
A2: 1580 | B2: 0 | C2: 32.1053 | D2: 80 | E2: 98.7368 | G2: 1581 | H2: 0 | I2: 28.4 | J2: 57 | K2: 105.8 | M2: 1582 | N2: 0 | O2: 24.3824 | P2: 72 | Q2: 99.8529 | S2: 1583 | T2: 0 | U2: 30.2917 | V2: 62 | W2: 105.5833 | Y2: 1585 | Z2: 0 | AA2: 22.6786 | AB2: 70 | AC2: 101.6429 | AE2: 1586 | AF2: 0 | AG2: 26.5357 | AH2: 67 | AI2: 104 | AK2: 1587 | AL2: 0 | AM2: 28.6 | AN2: 72 | AO2: 96.3 | AQ2: 1588 | AR2: 0 | AS2: 26.1034 | AT2: 54 | AU2: 88.5862 | AW2: 1589 | AX2: 0 | AY2: 19.0833 | AZ2: 69 | BA2: 67.75 | BC2: 1590 | BD2: 0 | BE2: 24.2188 | BF2: 55 | BG2: 97.7188 | BI2: 1591 | BJ2: 0 | BK2: 29.1 | BL2: 61 | BM2: 70.8 | BO2: 1592 | BP2: 0 | BQ2: 30.2414 | BR2: 58 | BS2: 100.2759 | BU2: 1593 | BV2: 0 | BW2: 26.6364 | BX2: 67 | BY2: 100.4242 | CA2: 1594 | CB2: 0 | CC2: 14.9697 | CD2: 75 | CE2: 100.3333 | CG2: 1596 | CH2: 0 | CI2: 28.0278 | CJ2: 77 | CK2: 90.6667 | CM2: 1597 | CN2: 0 | CO2: 25.2821 | CP2: 68 | CQ2: 95.2821 | CS2: 1598 | CT2: 0 | CU2: 28.4 | CV2: 70 | CW2: 82.8286 | CY2: 1599 | CZ2: 0 | DA2: 20.9756 | DB2: 91 | DC2: 104.0732 | DE2: 1600 | DF2: 0 | DG2: 15.5333 | DH2: 77 | DI2: 103.7556
B3: 1 | C3: 32.4211 | D3: 81 | E3: 98.5 | H3: 1 | I3: 28.3667 | J3: 58 | K3: 104.4667 | N3: 1 | O3: 24.8824 | P3: 73 | Q3: 100.2059 | T3: 1 | U3: 31.0417 | V3: 63 | W3: 104.7917 | Z3: 1 | AA3: 23.6071 | AB3: 71 | AC3: 102.2857 | AF3: 1 | AG3: 26.8929 | AH3: 68 | AI3: 103.9643 | AL3: 1 | AM3: 29.3 | AN3: 73 | AO3: 96.7333 | AR3: 1 | AS3: 26.7586 | AT3: 55 | AU3: 88.7586 | AX3: 1 | AY3: 19.4167 | AZ3: 70 | BA3: 68.375 | BD3: 1 | BE3: 27.2812 | BF3: 56 | BG3: 97.5938 | BJ3: 1 | BK3: 29.5 | BL3: 62 | BM3: 70.15 | BP3: 1 | BQ3: 31.1034 | BR3: 59 | BS3: 100.7241 | BV3: 1 | BW3: 27.697 | BX3: 68 | BY3: 99 | CB3: 1 | CC3: 17.1818 | CD3: 76 | CE3: 100.0303 | CH3: 1 | CI3: 28.5278 | CJ3: 78 | CK3: 90.1944 | CN3: 1 | CO3: 25.7179 | CP3: 69 | CQ3: 95.6154 | CT3: 1 | CU3: 28.7429 | CV3: 71 | CW3: 82.8857 | CZ3: 1 | DA3: 22.2195 | DB3: 92 | DC3: 104.5366 | DF3: 1 | DG3: 15.6222 | DH3: 78 | DI3: 103.6222
B4: 2 | C4: 33.4737 | D4: 82 | E4: 98.3684 | H4: 2 | I4: 28.2 | J4: 59 | K4: 102.3 | N4: 2 | O4: 25.5882 | P4: 74 | Q4: 99.9706 | T4: 2 | U4: 32.5417 | V4: 64 | W4: 103.2083 | Z4: 2 | AA4: 25.0357 | AB4: 72 | AC4: 102.5 | AF4: 2 | AG4: 27.1786 | AH4: 69 | AI4: 104.1071 | AL4: 2 | AM4: 29.7 | AN4: 74 | AO4: 96.7333 | AR4: 2 | AS4: 27.4828 | AT4: 56 | AU4: 88.8276 | AX4: 2 | AY4: 20.375 | AZ4: 71 | BA4: 68.9583 | BD4: 2 | BE4: 31.7188 | BF4: 57 | BG4: 97.1875 | BJ4: 2 | BK4: 30.35 | BL4: 63 | BM4: 70.1 | BP4: 2 | BQ4: 32.1034 | BR4: 60 | BS4: 101.2759 | BV4: 2 | BW4: 29.0303 | BX4: 69 | BY4: 97.8182 | CB4: 2 | CC4: 19.4545 | CD4: 77 | CE4: 98.1818 | CH4: 2 | CI4: 29.25 | CJ4: 79 | CK4: 89.8889 | CN4: 2 | CO4: 26.8462 | CP4: 70 | CQ4: 95.9744 | CT4: 2 | CU4: 29.1429 | CV4: 72 | CW4: 83.0857 | CZ4: 2 | DA4: 23.2683 | DB4: 93 | DC4: 105.5366 | DF4: 2 | DG4: 16.2444 | DH4: 79 | DI4: 103.0222
B5: 3 | C5: 34.4737 | D5: 83 | E5: 97.6316 | H5: 3 | I5: 28.5 | J5: 60 | K5: 98.6667 | N5: 3 | O5: 26.2353 | P5: 75 | Q5: 99.0588 | T5: 3 | U5: 34 | V5: 65 | W5: 102.0417 | Z5: 3 | AA5: 26.4286 | AB5: 73 | AC5: 102.1786 | AF5: 3 | AG5: 27.6071 | AH5: 70 | AI5: 104.0714 | AL5: 3 | AM5: 29.8333 | AN5: 75 | AO5: 96.9667 | AR5: 3 | AS5: 27.5517 | AT5: 57 | AU5: 88.4483 | AX5: 3 | AY5: 21.4167 | AZ5: 72 | BA5: 69.5 | BD5: 3 | BE5: 36.4375 | BF5: 58 | BG5: 96.6875 | BJ5: 3 | BK5: 31.7 | BL5: 64 | BM5: 70.3 | BP5: 3 | BQ5: 32.5517 | BR5: 61 | BS5: 100.8621 | BV5: 3 | BW5: 30.0606 | BX5: 70 | BY5: 96.8788 | CB5: 3 | CC5: 20.8182 | CD5: 78 | CE5: 95.8788 | CH5: 3 | CI5: 29.9722 | CJ5: 80 | CK5: 89.5278 | CN5: 3 | CO5: 27.5128 | CP5: 71 | CQ5: 95.4872 | CT5: 3 | CU5: 29.6286 | CV5: 73 | CW5: 83.4286 | CZ5: 3 | DA5: 23.5366 | DB5: 94 | DC5: 107.0732 | DF5: 3 | DG5: 17.2222 | DH5: 80 | DI5: 102.1111
B6: 4 | C6: 35.3421 | D6: 84 | E6: 96.8421 | H6: 4 | I6: 28.9 | J6: 61 | K6: 96.5 | N6: 4 | O6: 26.8235 | P6: 76 | Q6: 97.9118 | T6: 4 | U6: 34.4583 | V6: 66 | W6: 101 | Z6: 4 | AA6: 27.3214 | AB6: 74 | AC6: 101.7143 | AF6: 4 | AG6: 28.6786 | AH6: 71 | AI6: 103.6786 | AL6: 4 | AM6: 30.0333 | AN6: 76 | AO6: 97.5667 | AR6: 4 | AS6: 27.8276 | AT6: 58 | AU6: 87.9655 | AX6: 4 | AY6: 21.9167 | AZ6: 73 | BA6: 70.375 | BD6: 4 | BE6: 44.75 | BF6: 59 | BG6: 96 | BJ6: 4 | BK6: 32.1 | BL6: 65 | BM6: 70.1 | BP6: 4 | BQ6: 33.1034 | BR6: 62 | BS6: 99.6897 | BV6: 4 | BW6: 31.2727 | BX6: 71 | BY6: 95.697 | CB6: 4 | CC6: 21.0606 | CD6: 79 | CE6: 93.7576 | CH6: 4 | CI6: 30.3611 | CJ6: 81 | CK6: 89.7222 | CN6: 4 | CO6: 27.8205 | CP6: 72 | CQ6: 95.5128 | CT6: 4 | CU6: 30.2 | CV6: 74 | CW6: 84.0857 | CZ6: 4 | DA6: 23.3659 | DB6: 95 | DC6: 108.5122 | DF6: 4 | DG6: 19.1111 | DH6: 81 | DI6: 101.3778
B7: 5 | C7: 35.7895 | D7: 85 | E7: 96.6053 | H7: 5 | I7: 29.6333 | J7: 62 | K7: 95.6667 | N7: 5 | O7: 27.5 | P7: 77 | Q7: 97.1765 | T7: 5 | U7: 34.7083 | V7: 67 | W7: 100.0833 | Z7: 5 | AA7: 27.2857 | AB7: 75 | AC7: 101.6429 | AF7: 5 | AG7: 30.0714 | AH7: 72 | AI7: 103 | AL7: 5 | AM7: 30.1333 | AN7: 77 | AO7: 98.2667 | AR7: 5 | AS7: 28.3103 | AT7: 59 | AU7: 87.2759 | AX7: 5 | AY7: 22.2917 | AZ7: 74 | BA7: 71 | BD7: 5 | BE7: 56.4375 | BF7: 60 | BG7: 95.5938 | BJ7: 5 | BK7: 32.3 | BL7: 66 | BM7: 69.85 | BP7: 5 | BQ7: 34.3448 | BR7: 63 | BS7: 98.0345 | BV7: 5 | BW7: 32.6667 | BX7: 72 | BY7: 94.9394 | CB7: 5 | CC7: 21.303 | CD7: 80 | CE7: 92.2424 | CH7: 5 | CI7: 30.5556 | CJ7: 82 | CK7: 89.9444 | CN7: 5 | CO7: 28.6923 | CP7: 73 | CQ7: 95.3846 | CT7: 5 | CU7: 30.7143 | CV7: 75 | CW7: 84 | CZ7: 5 | DA7: 23.439 | DB7: 96 | DC7: 109.5122 | DF7: 5 | DG7: 21.2889 | DH7: 82 | DI7: 100.7556
B8: 6 | C8: 36.4474 | D8: 86 | E8: 96.5263 | H8: 6 | I8: 29.9 | J8: 63 | K8: 95.3 | N8: 6 | O8: 28 | P8: 78 | Q8: 96.5882 | T8: 6 | U8: 35.3333 | V8: 68 | W8: 99.1667 | Z8: 6 | AA8: 26.9643 | AB8: 76 | AC8: 101.2857 | AF8: 6 | AG8: 30.4286 | AH8: 73 | AI8: 101.3214 | AL8: 6 | AM8: 30.4667 | AN8: 78 | AO8: 98.7667 | AR8: 6 | AS8: 29.3103 | AT8: 60 | AU8: 86.6897 | AX8: 6 | AY8: 22.4583 | AZ8: 75 | BA8: 71.7083 | BD8: 6 | BE8: 65.3125 | BF8: 61 | BG8: 94.6875 | BJ8: 6 | BK8: 32.85 | BL8: 67 | BM8: 69.35 | BP8: 6 | BQ8: 35.6897 | BR8: 64 | BS8: 97.0345 | BV8: 6 | BW8: 33.9697 | BX8: 73 | BY8: 94.5152 | CB8: 6 | CC8: 21.3636 | CD8: 81 | CE8: 90.1515 | CH8: 6 | CI8: 30.9722 | CJ8: 83 | CK8: 89.9444 | CN8: 6 | CO8: 30.2308 | CP8: 74 | CQ8: 95.0513 | CT8: 6 | CU8: 31.1714 | CV8: 76 | CW8: 82.9429 | CZ8: 6 | DA8: 23.8049 | DB8: 97 | DC8: 110.3171 | DF8: 6 | DG8: 23.0667 | DH8: 83 | DI8: 100.0667
B9: 7 | C9: 36.9474 | D9: 87 | E9: 96.1579 | H9: 7 | I9: 30 | J9: 64 | K9: 94.9667 | N9: 7 | O9: 28.5588 | P9: 79 | Q9: 96 | T9: 7 | U9: 35.5833 | V9: 69 | W9: 98.125 | Z9: 7 | AA9: 27 | AB9: 77 | AC9: 100.2143 | AF9: 7 | AG9: 30 | AH9: 74 | AI9: 100.1429 | AL9: 7 | AM9: 30.7333 | AN9: 79 | AO9: 98.3 | AR9: 7 | AS9: 29.7241 | AT9: 61 | AU9: 86.0345 | AX9: 7 | AY9: 22.25 | AZ9: 76 | BA9: 72.5 | BD9: 7 | BE9: 69.5 | BF9: 62 | BG9: 93.6875 | BJ9: 7 | BK9: 33.6 | BL9: 68 | BM9: 68.85 | BP9: 7 | BQ9: 36.6207 | BR9: 65 | BS9: 96.2759 | BV9: 7 | BW9: 34.7879 | BX9: 74 | BY9: 93.6667 | CB9: 7 | CC9: 21.2727 | CD9: 82 | CE9: 88.7576 | CH9: 7 | CI9: 31.3889 | CJ9: 84 | CK9: 89.8889 | CN9: 7 | CO9: 31.0769 | CP9: 75 | CQ9: 94.9231 | CT9: 7 | CU9: 31.6857 | CV9: 77 | CW9: 82.1429 | CZ9: 7 | DA9: 24.1707 | DB9: 98 | DC9: 111.1463 | DF9: 7 | DG9: 24.8444 | DH9: 84 | DI9: 99.2667
B10: 8 | C10: 37.0263 | D10: 88 | E10: 95.6316 | H10: 8 | I10: 30.2333 | J10: 65 | K10: 92.9 | N10: 8 | O10: 29 | P10: 80 | Q10: 95.4706 | T10: 8 | U10: 36.1667 | V10: 70 | W10: 97.375 | Z10: 8 | AA10: 27.8929 | AB10: 78 | AC10: 98.8929 | AF10: 8 | AG10: 30.5714 | AH10: 75 | AI10: 98.5 | AL10: 8 | AM10: 31.0667 | AN10: 80 | AO10: 97.8 | AR10: 8 | AS10: 29.931 | AT10: 62 | AU10: 85.3103 | AX10: 8 | AY10: 22.4167 | AZ10: 77 | BA10: 72.625 | BD10: 8 | BE10: 71.0938 | BF10: 63 | BG10: 92.9062 | BJ10: 8 | BK10: 35 | BL10: 69 | BM10: 67.95 | BP10: 8 | BQ10: 37.5517 | BR10: 66 | BS10: 95.4828 | BV10: 8 | BW10: 35.1212 | BX10: 75 | BY10: 91.8485 | CB10: 8 | CC10: 21.6364 | CD10: 83 | CE10: 87.8485 | CH10: 8 | CI10: 31.8333 | CJ10: 85 | CK10: 89.75 | CN10: 8 | CO10: 31.8462 | CP10: 76 | CQ10: 95 | CT10: 8 | CU10: 32.1714 | CV10: 78 | CW10: 80.7429 | CZ10: 8 | DA10: 24.5854 | DB10: 99 | DC10: 111.2195 | DF10: 8 | DG10: 26.3556 | DH10: 85 | DI10: 98.3778
B11: 9 | C11: 36.8684 | D11: 89 | E11: 94.9211 | H11: 9 | I11: 30.5333 | J11: 66 | K11: 89 | N11: 9 | O11: 29.3529 | P11: 81 | Q11: 95 | T11: 9 | U11: 37.375 | V11: 71 | W11: 95.7917 | Z11: 9 | AA11: 28.4643 | AB11: 79 | AC11: 97.9286 | AF11: 9 | AG11: 31.75 | AH11: 76 | AI11: 95.8929 | AL11: 9 | AM11: 31.2333 | AN11: 81 | AO11: 98 | AR11: 9 | AS11: 31.1034 | AT11: 63 | AU11: 84.5517 | AX11: 9 | AY11: 23.375 | AZ11: 78 | BA11: 72.0417 | BD11: 9 | BE11: 70.8438 | BF11: 64 | BG11: 92.25 | BJ11: 9 | BK11: 36 | BL11: 70 | BM11: 67.2 | BP11: 9 | BQ11: 38.1724 | BR11: 67 | BS11: 94.8276 | BV11: 9 | BW11: 35.1515 | BX11: 76 | BY11: 88.8182 | CB11: 9 | CC11: 22.7576 | CD11: 84 | CE11: 86.3333 | CH11: 9 | CI11: 32.25 | CJ11: 86 | CK11: 89.2778 | CN11: 9 | CO11: 32.4359 | CP11: 77 | CQ11: 94.6667 | CT11: 9 | CU11: 32.9429 | CV11: 79 | CW11: 77.3429 | CZ11: 9 | DA11: 26.2439 | DB11: 100 | DC11: 111.3171 | DF11: 9 | DG11: 27.5778 | DH11: 86 | DI11: 97.0667
B12: 10 | C12: 37.0789 | D12: 90 | E12: 93.8421 | H12: 10 | I12: 31.1 | J12: 67 | K12: 84.5333 | N12: 10 | O12: 29.7353 | P12: 82 | Q12: 94.7647 | T12: 10 | U12: 38.7083 | V12: 72 | W12: 94.2083 | Z12: 10 | AA12: 28.9286 | AB12: 80 | AC12: 96.9286 | AF12: 10 | AG12: 33.0357 | AH12: 77 | AI12: 92.3929 | AL12: 10 | AM12: 31.3667 | AN12: 82 | AO12: 97.6 | AR12: 10 | AS12: 33.1724 | AT12: 64 | AU12: 84.0345 | AX12: 10 | AY12: 24.3333 | AZ12: 79 | BA12: 71.7917 | BD12: 10 | BE12: 70 | BF12: 65 | BG12: 91.75 | BJ12: 10 | BK12: 36.7 | BL12: 71 | BM12: 67.45 | BP12: 10 | BQ12: 39.6552 | BR12: 68 | BS12: 94.2414 | BV12: 10 | BW12: 34.8182 | BX12: 77 | BY12: 84.8182 | CB12: 10 | CC12: 23.9091 | CD12: 85 | CE12: 84.5455 | CH12: 10 | CI12: 32.6667 | CJ12: 87 | CK12: 88.9722 | CN12: 10 | CO12: 32.6923 | CP12: 78 | CQ12: 93.7949 | CT12: 10 | CU12: 34.2571 | CV12: 80 | CW12: 72.6571 | CZ12: 10 | DA12: 27.6585 | DB12: 101 | DC12: 111.4146 | DF12: 10 | DG12: 28.3778 | DH12: 87 | DI12: 95.8222
B13: 11 | C13: 37.3947 | D13: 91 | E13: 92.3158 | H13: 11 | I13: 31.2 | J13: 68 | K13: 79.6 | N13: 11 | O13: 30.1765 | P13: 83 | Q13: 94.5 | T13: 11 | U13: 40.125 | V13: 73 | W13: 93.2917 | Z13: 11 | AA13: 28.8929 | AB13: 81 | AC13: 96 | AF13: 11 | AG13: 34.0357 | AH13: 78 | AI13: 89.3929 | AL13: 11 | AM13: 32.1 | AN13: 83 | AO13: 96.3 | AR13: 11 | AS13: 34.7241 | AT13: 65 | AU13: 82.8276 | AX13: 11 | AY13: 25.0417 | AZ13: 80 | BA13: 71.125 | BD13: 11 | BE13: 69.375 | BF13: 66 | BG13: 91.2812 | BJ13: 11 | BK13: 37.35 | BL13: 72 | BM13: 67.7 | BP13: 11 | BQ13: 40.9655 | BR13: 69 | BS13: 93.3793 | BV13: 11 | BW13: 34.3939 | BX13: 78 | BY13: 80.5455 | CB13: 11 | CC13: 24.6364 | CD13: 86 | CE13: 82.7273 | CH13: 11 | CI13: 32.8333 | CJ13: 88 | CK13: 87.9444 | CN13: 11 | CO13: 33 | CP13: 79 | CQ13: 92.4615 | CT13: 11 | CU13: 35.5429 | CV13: 81 | CW13: 68 | CZ13: 11 | DA13: 28.4146 | DB13: 102 | DC13: 111.5854 | DF13: 11 | DG13: 29 | DH13: 88 | DI13: 94.1111
B14: 12 | C14: 37.8158 | D14: 92 | E14: 90.6316 | H14: 12 | I14: 31.9333 | J14: 69 | K14: 75.6333 | N14: 12 | O14: 31.1471 | P14: 84 | Q14: 93.8529 | T14: 12 | U14: 41.9167 | V14: 74 | W14: 93.125 | Z14: 12 | AA14: 29.4643 | AB14: 82 | AC14: 94.6071 | AF14: 12 | AG14: 33.9286 | AH14: 79 | AI14: 87.9286 | AL14: 12 | AM14: 32.8333 | AN14: 84 | AO14: 93.7667 | AR14: 12 | AS14: 35.5862 | AT14: 66 | AU14: 81.1724 | AX14: 12 | AY14: 25.625 | AZ14: 81 | BA14: 69.375 | BD14: 12 | BE14: 68.9062 | BF14: 67 | BG14: 90.125 | BJ14: 12 | BK14: 37.4 | BL14: 73 | BM14: 67.55 | BP14: 12 | BQ14: 41.0345 | BR14: 70 | BS14: 92.6897 | BV14: 12 | BW14: 34.7273 | BX14: 79 | BY14: 76.6364 | CB14: 12 | CC14: 25.0606 | CD14: 87 | CE14: 79.9697 | CH14: 12 | CI14: 32.6389 | CJ14: 89 | CK14: 86.9167 | CN14: 12 | CO14: 34.1795 | CP14: 80 | CQ14: 90.7436 | CT14: 12 | CU14: 36.3429 | CV14: 82 | CW14: 65 | CZ14: 12 | DA14: 29.2195 | DB14: 103 | DC14: 111.8781 | DF14: 12 | DG14: 29.9333 | DH14: 89 | DI14: 92.3556
... B55: 53 | C55: 88.7895 | D55: 133 | E55: 48.4737 | H55: 53 | I55: 96.1667 | J55: 110 | K55: 29.2333 | N55: 53 | O55: 90.0294 | P55: 125 | Q55: 40.2647 | T55: 53 | U55: 96.5833 | V55: 115 | W55: 33.1667 | Z55: 53 | AA55: 78.5357 | AB55: 123 | AC55: 37.5 | AF55: 53 | AG55: 83.2857 | AH55: 120 | AI55: 33.4286 | AL55: 53 | AM55: 57.3667 | AN55: 125 | AO55: 42.7667 | AR55: 53 | AS55: 88.7586 | AT55: 107 | AU55: 34.2759 | AX55: 53 | AY55: 74 | AZ55: 122 | BA55: 30.25 | BD55: 53 | BE55: 96.9688 | BF55: 108 | BG55: 22.875 | BJ55: 53 | BK55: 72 | BL55: 114 | BM55: 32.15 | BP55: 53 | BQ55: 99.2069 | BR55: 111 | BS55: 31.8621 | BV55: 53 | BW55: 102.303 | BX55: 120 | BY55: 36.7273 | CB55: 53 | CC55: 77.6667 | CD55: 128 | CE55: 28.3939 | CH55: 53 | CI55: 70.1667 | CJ55: 130 | CK55: 40.2222 | CN55: 53 | CO55: 87.6154 | CP55: 121 | CQ55: 35.0256 | CT55: 53 | CU55: 71.8286 | CV55: 123 | CW55: 31 | CZ55: 53 | DA55: 68.6098 | DB55: 144 | DC55: 64.0732 | DF55: 53 | DG55: 92.1778 | DH55: 130 | DI55: 37.7778
B56: 54 | C56: 90.5789 | D56: 134 | E56: 47.0526 | H56: 54 | I56: 101.2333 | J56: 111 | K56: 29.1 | N56: 54 | O56: 92 | P56: 126 | Q56: 39.8529 | T56: 54 | U56: 98.9583 | V56: 116 | W56: 33.4167 | Z56: 54 | AA56: 80.1429 | AB56: 124 | AC56: 36.4286 | AF56: 54 | AG56: 84.6071 | AH56: 121 | AI56: 33.6786 | AL56: 54 | AM56: 58.9667 | AN56: 126 | AO56: 42.5 | AX56: 54 | AY56: 75.5417 | AZ56: 123 | BA56: 29.2917 | BD56: 54 | BE56: 97.5625 | BF56: 109 | BG56: 21.8125 | BJ56: 54 | BK56: 71.95 | BL56: 115 | BM56: 31.8 | BP56: 54 | BQ56: 99.0345 | BR56: 112 | BS56: 31.6897 | BV56: 54 | BW56: 104.0303 | BX56: 121 | BY56: 35.4242 | CB56: 54 | CC56: 78.8485 | CD56: 129 | CE56: 28.4545 | CH56: 54 | CI56: 71.4444 | CJ56: 131 | CK56: 40.0278 | CN56: 54 | CO56: 87.7692 | CP56: 122 | CQ56: 34.1282 | CT56: 54 | CU56: 73.5429 | CV56: 124 | CW56: 30.4571 | CZ56: 54 | DA56: 69.0488 | DB56: 145 | DC56: 63.878 | DF56: 54 | DG56: 92.9333 | DH56: 131 | DI56: 37
B57: 55 | C57: 91.8421 | D57: 135 | E57: 45.8947 | H57: 55 | I57: 105.5667 | J57: 112 | K57: 28.7667 | N57: 55 | O57: 93.2647 | P57: 127 | Q57: 38.7353 | T57: 55 | U57: 102.375 | V57: 117 | W57: 34 | Z57: 55 | AA57: 82.2143 | AB57: 125 | AC57: 35.0714 | AF57: 55 | AG57: 85.7143 | AH57: 122 | AI57: 33.4643 | AL57: 55 | AM57: 59.7667 | AN57: 127 | AO57: 41.7 | AX57: 55 | AY57: 76.4167 | AZ57: 124 | BA57: 28.5 | BJ57: 55 | BK57: 71.85 | BL57: 116 | BM57: 31.55 | BP57: 55 | BQ57: 99 | BR57: 113 | BS57: 31.3103 | BV57: 55 | BW57: 105.2424 | BX57: 122 | BY57: 34.3939 | CB57: 55 | CC57: 80.3636 | CD57: 130 | CE57: 28.6061 | CH57: 55 | CI57: 72.75 | CJ57: 132 | CK57: 39.9444 | CN57: 55 | CO57: 87.7949 | CP57: 123 | CQ57: 33.1795 | CT57: 55 | CU57: 75.7429 | CV57: 125 | CW57: 30.4857 | CZ57: 55 | DA57: 69.2195 | DB57: 146 | DC57: 63.4634 | DF57: 55 | DG57: 93.2667 | DH57: 132 | DI57: 36.3556
B58: 56 | C58: 92.9211 | D58: 136 | E58: 45.3158 | H58: 56 | I58: 107.1333 | J58: 113 | K58: 28.3667 | N58: 56 | O58: 94 | P58: 128 | Q58: 37.4118 | T58: 56 | U58: 105.3333 | V58: 118 | W58: 35.1667 | Z58: 56 | AA58: 84.3571 | AB58: 126 | AC58: 34.1429 | AF58: 56 | AG58: 86.9643 | AH58: 123 | AI58: 32.75 | AL58: 56 | AM58: 60.6667 | AN58: 128 | AO58: 40.8 | AX58: 56 | AY58: 76.7917 | AZ58: 125 | BA58: 27.75 | BJ58: 56 | BK58: 72 | BL58: 117 | BM58: 31.05 | BP58: 56 | BQ58: 99.5172 | BR58: 114 | BS58: 30.7241 | BV58: 56 | BW58: 106.2424 | BX58: 123 | BY58: 33.1515 | CB58: 56 | CC58: 81.9394 | CD58: 131 | CE58: 28.6061 | CH58: 56 | CI58: 74.9722 | CJ58: 133 | CK58: 39.8056 | CN58: 56 | CO58: 87.9744 | CP58: 124 | CQ58: 32.4103 | CT58: 56 | CU58: 77.2 | CV58: 126 | CW58: 30.1429 | CZ58: 56 | DA58: 68.8049 | DB58: 147 | DC58: 63.3171 | DF58: 56 | DG58: 94.2 | DH58: 133 | DI58: 35.8889
B59: 57 | C59: 93.5789 | D59: 137 | E59: 44.6316 | N59: 57 | O59: 93.9412 | P59: 129 | Q59: 35.7941 | T59: 57 | U59: 107.125 | V59: 119 | W59: 35.9167 | Z59: 57 | AA59: 86.9643 | AB59: 127 | AC59: 33.9643 | AF59: 57 | AG59: 89.3214 | AH59: 124 | AI59: 31.6786 | AL59: 57 | AM59: 62.4 | AN59: 129 | AO59: 40.2 | AX59: 57 | AY59: 76.75 | AZ59: 126 | BA59: 27.8333 | BJ59: 57 | BK59: 72.4 | BL59: 118 | BM59: 30.85 | BP59: 57 | BQ59: 99.8276 | BR59: 115 | BS59: 29.9655 | BV59: 57 | BW59: 106.9091 | BX59: 124 | BY59: 32.4242 | CB59: 57 | CC59: 83.1212 | CD59: 132 | CE59: 28.1515 | CH59: 57 | CI59: 77.25 | CJ59: 134 | CK59: 39.4722 | CN59: 57 | CO59: 88.641 | CP59: 125 | CQ59: 31.641 | CT59: 57 | CU59: 77.8857 | CV59: 127 | CW59: 29.7429 | CZ59: 57 | DA59: 68.0488 | DB59: 148 | DC59: 63.2439 | DF59: 57 | DG59: 95 | DH59: 134 | DI59: 34.6444
B60: 58 | C60: 94.1579 | D60: 138 | E60: 43.3158 | N60: 58 | O60: 93.9412 | P60: 130 | Q60: 34.7647 | T60: 58 | U60: 107.9583 | V60: 120 | W60: 35.25 | Z60: 58 | AA60: 88.8571 | AB60: 128 | AC60: 33.7857 | AF60: 58 | AG60: 91.9286 | AH60: 125 | AI60: 30.8571 | AL60: 58 | AM60: 64.8667 | AN60: 130 | AO60: 39.7333 | AX60: 58 | AY60: 76.125 | AZ60: 127 | BA60: 28.125 | BJ60: 58 | BK60: 72.2 | BL60: 119 | BM60: 30.2 | BV60: 58 | BW60: 107.0909 | BX60: 125 | BY60: 32.0909 | CB60: 58 | CC60: 84.5455 | CD60: 133 | CE60: 28.1515 | CH60: 58 | CI60: 79.1111 | CJ60: 135 | CK60: 38.75 | CN60: 58 | CO60: 89.6154 | CP60: 126 | CQ60: 30.5385 | CT60: 58 | CU60: 78.2 | CV60: 128 | CW60: 29.2857 | CZ60: 58 | DA60: 67.9024 | DB60: 149 | DC60: 62.8049 | DF60: 58 | DG60: 95.2444 | DH60: 135 | DI60: 34.0222
B61: 59 | C61: 94.5 | D61: 139 | E61: 42.4737 | N61: 59 | O61: 94.7647 | P61: 131 | Q61: 34 | T61: 59 | U61: 108.0833 | V61: 121 | W61: 33.75 | Z61: 59 | AA61: 90.25 | AB61: 129 | AC61: 32.7857 | AF61: 59 | AG61: 95.3929 | AH61: 126 | AI61: 30.7143 | AL61: 59 | AM61: 66.9 | AN61: 131 | AO61: 39.3333 | AX61: 59 | AY61: 75.0417 | AZ61: 128 | BA61: 27.4167 | BJ61: 59 | BK61: 71.6 | BL61: 120 | BM61: 30.15 | BV61: 59 | BW61: 107.2121 | BX61: 126 | BY61: 32 | CB61: 59 | CC61: 86.4242 | CD61: 134 | CE61: 28.4242 | CH61: 59 | CI61: 80.8056 | CJ61: 136 | CK61: 37.6389 | CN61: 59 | CO61: 90.5641 | CP61: 127 | CQ61: 29.359 | CT61: 59 | CU61: 78.1429 | CV61: 129 | CW61: 29.2857 | CZ61: 59 | DA61: 69.3659 | DB61: 150 | DC61: 62.6585 | DF61: 59 | DG61: 95.4 | DH61: 136 | DI61: 34.1778
B62: 60 | C62: 94.5789 | D62: 140 | E62: 41.7105 | N62: 60 | O62: 95.4412 | P62: 132 | Q62: 32.7647 | T62: 60 | U62: 106.9167 | V62: 122 | W62: 32.375 | Z62: 60 | AA62: 91.1071 | AB62: 130 | AC62: 30.9286 | AF62: 60 | AG62: 98.4286 | AH62: 127 | AI62: 30.6071 | AL62: 60 | AM62: 68.7 | AN62: 132 | AO62: 38.8333 | AX62: 60 | AY62: 73.4167 | AZ62: 129 | BA62: 26 | BJ62: 60 | BK62: 71.15 | BL62: 121 | BM62: 29.9 | BV62: 60 | BW62: 107.6667 | BX62: 127 | BY62: 31.0909 | CB62: 60 | CC62: 87.6364 | CD62: 135 | CE62: 28.0606 | CH62: 60 | CI62: 82.3889 | CJ62: 137 | CK62: 36.25 | CN62: 60 | CO62: 91.1538 | CP62: 128 | CQ62: 28.2051 | CT62: 60 | CU62: 78.5714 | CV62: 130 | CW62: 29.0857 | CZ62: 60 | DA62: 72.2195 | DB62: 151 | DC62: 62.5122 | DF62: 60 | DG62: 95.3556 | DH62: 137 | DI62: 34.0222
B63: 61 | C63: 94.7105 | D63: 141 | E63: 40.7632 | N63: 61 | O63: 95.6765 | P63: 133 | Q63: 31.8529 | T63: 61 | U63: 105.5417 | V63: 123 | W63: 32.0417 | Z63: 61 | AA63: 91.8929 | AB63: 131 | AC63: 28.5714 | AF63: 61 | AG63: 100.8929 | AH63: 128 | AI63: 30.1071 | AL63: 61 | AM63: 70.9667 | AN63: 133 | AO63: 38.2 | AX63: 61 | AY63: 71.7917 | AZ63: 130 | BA63: 24.7083 | BV63: 61 | BW63: 107.9697 | BX63: 128 | BY63: 29.9697 | CB63: 61 | CC63: 87.7273 | CD63: 136 | CE63: 27.2121 | CH63: 61 | CI63: 83.7778 | CJ63: 138 | CK63: 35 | CN63: 61 | CO63: 92.0513 | CP63: 129 | CQ63: 27.4872 | CT63: 61 | CU63: 79.2286 | CV63: 131 | CW63: 28.8286 | CZ63: 61 | DA63: 75.2927 | DB63: 152 | DC63: 61.8537 | DF63: 61 | DG63: 95.5111 | DH63: 138 | DI63: 33.4
B64: 62 | C64: 95.6316 | D64: 142 | E64: 40.5526 | N64: 62 | O64: 96.0882 | P64: 134 | Q64: 31.1471 | Z64: 62 | AA64: 92.8571 | AB64: 132 | AC64: 27.5 | AF64: 62 | AG64: 102.2857 | AH64: 129 | AI64: 29.9643 | AL64: 62 | AM64: 73.2667 | AN64: 134 | AO64: 37.9667 | AX64: 62 | AY64: 70.1667 | AZ64: 131 | BA64: 23.7083 | BV64: 62 | BW64: 107.3636 | BX64: 129 | BY64: 29.0303 | CB64: 62 | CC64: 88.2727 | CD64: 137 | CE64: 26.7273 | CH64: 62 | CI64: 85.2222 | CJ64: 139 | CK64: 34.4167 | CN64: 62 | CO64: 93.3077 | CP64: 130 | CQ64: 27.1282 | CT64: 62 | CU64: 80.1429 | CV64: 132 | CW64: 28.2 | CZ64: 62 | DA64: 76.9756 | DB64: 153 | DC64: 60.2927 | DF64: 62 | DG64: 96.3333 | DH64: 139 | DI64: 32.9333
B65: 63 | C65: 96.5789 | D65: 143 | E65: 40.7105 | N65: 63 | O65: 96.4706 | P65: 135 | Q65: 30.5588 | Z65: 63 | AA65: 93.7857 | AB65: 133 | AC65: 27.1429 | AF65: 63 | AG65: 102.8214 | AH65: 130 | AI65: 29.6071 | AL65: 63 | AM65: 75.6667 | AN65: 135 | AO65: 37.4667 | AX65: 63 | AY65: 68.8333 | AZ65: 132 | BA65: 22.9583 | BV65: 63 | BW65: 106.303 | BX65: 130 | BY65: 28.3333 | CB65: 63 | CC65: 89.9091 | CD65: 138 | CE65: 26.6364 | CH65: 63 | CI65: 86.5556 | CJ65: 140 | CK65: 34.2222 | CN65: 63 | CO65: 94.0513 | CP65: 131 | CQ65: 26.9231 | CT65: 63 | CU65: 81.1143 | CV65: 133 | CW65: 27.4 | CZ65: 63 | DA65: 76.1463 | DB65: 154 | DC65: 59.122 | DF65: 63 | DG65: 97.2667 | DH65: 140 | DI65: 32.2889
B66: 64 | C66: 97.4737 | D66: 144 | E66: 41.2632 | N66: 64 | O66: 96.8824 | P66: 136 | Q66: 29.9412 | Z66: 64 | AA66: 94.6071 | AB66: 134 | AC66: 27 | AF66: 64 | AG66: 103.3214 | AH66: 131 | AI66: 29.3571 | AL66: 64 | AM66: 77.2333 | AN66: 136 | AO66: 36.4333 | AX66: 64 | AY66: 67.75 | AZ66: 133 | BA66: 22 | BV66: 64 | BW66: 104.7576 | BX66: 131 | BY66: 27.8182 | CB66: 64 | CC66: 91.8788 | CD66: 139 | CE66: 26.9394 | CH66: 64 | CI66: 88.1944 | CJ66: 141 | CK66: 33.8333 | CN66: 64 | CO66: 94.3333 | CP66: 132 | CQ66: 26.7949 | CT66: 64 | CU66: 82.2857 | CV66: 134 | CW66: 26.5714 | CZ66: 64 | DA66: 73.8537 | DB66: 155 | DC66: 58.9512 | DF66: 64 | DG66: 97.6222 | DH66: 141 | DI66: 31.4667
B67: 65 | C67: 98.9474 | D67: 145 | E67: 40.4211 | N67: 65 | O67: 97.5294 | P67: 137 | Q67: 29.2353 | Z67: 65 | AA67: 95.6786 | AB67: 135 | AC67: 26.8571 | AF67: 65 | AG67: 103.6071 | AH67: 132 | AI67: 29.1071 | AL67: 65 | AM67: 79.5333 | AN67: 137 | AO67: 34.7667 | AX67: 65 | AY67: 67.7917 | AZ67: 134 | BA67: 20.7917 | BV67: 65 | BW67: 103.2727 | BX67: 132 | BY67: 27.3939 | CB67: 65 | CC67: 93.4848 | CD67: 140 | CE67: 26.9394 | CH67: 65 | CI67: 89.7778 | CJ67: 142 | CK67: 33.4444 | CN67: 65 | CO67: 94.3846 | CP67: 133 | CQ67: 26.7436 | CT67: 65 | CU67: 83.1143 | CV67: 135 | CW67: 26.1714 | CZ67: 65 | DA67: 73.2439 | DB67: 156 | DC67: 58.9024 | DF67: 65 | DG67: 98.2222 | DH67: 142 | DI67: 29.6222
B68: 66 | C68: 100.9737 | D68: 146 | E68: 39.1579 | N68: 66 | O68: 97.9706 | P68: 138 | Q68: 28.7941 | Z68: 66 | AA68: 96.75 | AB68: 136 | AC68: 26.6429 | AF68: 66 | AG68: 103.8929 | AH68: 133 | AI68: 29.0357 | AL68: 66 | AM68: 82.7667 | AN68: 138 | AO68: 33.4667 | AX68: 66 | AY68: 67.625 | AZ68: 135 | BA68: 19.75 | BV68: 66 | BW68: 101.7576 | BX68: 133 | BY68: 27.0909 | CB68: 66 | CC68: 94.697 | CD68: 141 | CE68: 25.4848 | CH68: 66 | CI68: 90.75 | CJ68: 143 | CK68: 32.5 | CN68: 66 | CO68: 94.5385 | CP68: 134 | CQ68: 26.5385 | CT68: 66 | CU68: 83.2857 | CV68: 136 | CW68: 26.0286 | CZ68: 66 | DA68: 75.1951 | DB68: 157 | DC68: 58.3659 | DF68: 66 | DG68: 99.6222 | DH68: 143 | DI68: 27.6
B69: 67 | C69: 103.0526 | D69: 147 | E69: 38.0789 | N69: 67 | O69: 98.4118 | P69: 139 | Q69: 28.3824 | Z69: 67 | AA69: 98 | AB69: 137 | AC69: 26.0357 | AL69: 67 | AM69: 86.2667 | AN69: 139 | AO69: 33.2333 | AX69: 67 | AY69: 66.9167 | AZ69: 136 | BA69: 19.125 | CB69: 67 | CC69: 95.8788 | CD69: 142 | CE69: 23.7879 | CH69: 67 | CI69: 91.5833 | CJ69: 144 | CK69: 31.4444 | CN69: 67 | CO69: 94.8205 | CP69: 135 | CQ69: 25.6667 | CT69: 67 | CU69: 83.1143 | CV69: 137 | CW69: 25.5714 | CZ69: 67 | DA69: 78.439 | DB69: 158 | DC69: 56.7805 | DF69: 67 | DG69: 101.2667 | DH69: 144 | DI69: 26.2444
B70: 68 | C70: 104.0526 | D70: 148 | E70: 37.4211 | N70: 68 | O70: 98.9706 | P70: 140 | Q70: 27.9118 | Z70: 68 | AA70: 99.0714 | AB70: 138 | AC70: 25.0714 | AL70: 68 | AM70: 89.1333 | AN70: 140 | AO70: 33.4 | AX70: 68 | AY70: 67.2083 | AZ70: 137 | BA70: 18.875 | CB70: 68 | CC70: 97.0303 | CD70: 143 | CE70: 22.3333 | CH70: 68 | CI70: 91.9444 | CJ70: 145 | CK70: 30.0556 | CT70: 68 | CU70: 82.8857 | CV70: 138 | CW70: 24.8286 | CZ70: 68 | DA70: 82.9024 | DB70: 159 | DC70: 54.6585 | DF70: 68 | DG70: 102.4667 | DH70: 145 | DI70: 24.6222
B71: 69 | C71: 103.8684 | D71: 149 | E71: 36.8947 | N71: 69 | O71: 99.5294 | P71: 141 | Q71: 27.4118 | Z71: 69 | AA71: 100.5 | AB71: 139 | AC71: 24.1786 | AL71: 69 | AM71: 91.4 | AN71: 141 | AO71: 32.9333 | CB71: 69 | CC71: 98.303 | CD71: 144 | CE71: 21.2727 | CH71: 69 | CI71: 91.8889 | CJ71: 146 | CK71: 29.25 | CT71: 69 | CU71: 82.8857 | CV71: 139 | CW71: 24.0286 | CZ71: 69 | DA71: 89.3659 | DB71: 160 | DC71: 52.122 | DF71: 69 | DG71: 103.4444 | DH71: 146 | DI71: 22.4889
B72: 70 | C72: 103.6316 | D72: 150 | E72: 36.6053 | N72: 70 | O72: 99.9412 | P72: 142 | Q72: 27.1765 | AL72: 70 | AM72: 93.4667 | AN72: 142 | AO72: 31.9 | CB72: 70 | CC72: 99.4242 | CD72: 145 | CE72: 20.4545 | CH72: 70 | CI72: 92.2778 | CJ72: 147 | CK72: 28.5833 | CZ72: 70 | DA72: 95.5366 | DB72: 161 | DC72: 50.2927 | DF72: 70 | DG72: 104.2667 | DH72: 147 | DI72: 20.2
B73: 71 | C73: 103.3421 | D73: 151 | E73: 35.8684 | N73: 71 | O73: 99.6471 | P73: 143 | Q73: 26.9412 | AL73: 71 | AM73: 94.8 | AN73: 143 | AO73: 30.9 | CB73: 71 | CC73: 100.1515 | CD73: 146 | CE73: 19.3939 | CH73: 71 | CI73: 92.9167 | CJ73: 148 | CK73: 27.8889 | CZ73: 71 | DA73: 98.561 | DB73: 162 | DC73: 48.6098 | DF73: 71 | DG73: 104.7333 | DH73: 148 | DI73: 18.6667
B74: 72 | C74: 102.4474 | D74: 152 | E74: 35.0789 | CB74: 72 | CC74: 100.1515 | CD74: 147 | CE74: 18.0606 | CH74: 72 | CI74: 92.7222 | CJ74: 149 | CK74: 27.25 | CZ74: 72 | DA74: 97.5366 | DB74: 163 | DC74: 47.0732 | DF74: 72 | DG74: 104.6667 | DH74: 149 | DI74: 18.3333
B75: 73 | C75: 101.4474 | D75: 153 | E75: 34.4737 | CB75: 73 | CC75: 100.1515 | CD75: 148 | CE75: 16.8788 | CH75: 73 | CI75: 92.0833 | CJ75: 150 | CK75: 26.6111 | CZ75: 73 | DA75: 92.3659 | DB75: 164 | DC75: 45.9024 | DF75: 73 | DG75: 104.6889 | DH75: 150 | DI75: 18.2444
B76: 74 | C76: 100.5789 | D76: 154 | E76: 33.5789 | CB76: 74 | CC76: 100.3636 | CD76: 149 | CE76: 15.4242 | CH76: 74 | CI76: 91.6944 | CJ76: 151 | CK76: 25.8056 | CZ76: 74 | DA76: 84.1219 | DB76: 165 | DC76: 44.3902 | DF76: 74 | DG76: 104.6 | DH76: 151 | DI76: 17.7111
B77: 75 | C77: 99.7105 | D77: 155 | E77: 33.0526 | CH77: 75 | CI77: 91.4444 | CJ77: 152 | CK77: 25.4444 | CZ77: 75 | DA77: 77.1951 | DB77: 166 | DC77: 43.0488 | DF77: 75 | DG77: 104.1556 | DH77: 152 | DI77: 16.6444
B78: 76 | C78: 99.1842 | D78: 156 | E78: 32.6316 | CH78: 76 | CI78: 91.1389 | CJ78: 153 | CK78: 25.0278 | CZ78: 76 | DA78: 77.3659 | DB78: 167 | DC78: 41.9024 | DF78: 76 | DG78: 103.8444 | DH78: 153 | DI78: 16.0667
B79: 77 | C79: 99.1842 | D79: 157 | E79: 32.2105 | CZ79: 77 | DA79: 82.0976 | DB79: 168 | DC79: 41.0732
B80: 78 | C80: 99 | D80: 158 | E80: 31.9211 | CZ80: 78 | DA80: 86.6341 | DB80: 169 | DC80: 39.7317
...

Sheet raw_b3a
A1: Image_ID | C1: L | E1: R | G1: Image_ID | I1: L | K1: R | M1: Image_ID | O1: L | Q1: R | S1: Image_ID | U1: L | W1: R | Y1: Image_ID | AA1: L | AC1: R | AE1: Image_ID | AG1: L | AI1: R | AK1: Image_ID | AM1: L | AO1: R | AQ1: Image_ID | AS1: L | AU1: R | AW1: Image_ID | AY1: L | BA1: R | BC1: Image_ID | BE1: L | BG1: R | BI1: Image_ID | BK1: L | BM1: R | BO1: Image_ID | BQ1: L | BS1: R | BU1: Image_ID | BW1: L | BY1: R | CA1: Image_ID | CC1: L | CE1: R
A2: 1562 | B2: 0 | C2: 20.4211 | D2: 63 | E2: 98.6316 | G2: 1566 | H2: 0 | I2: 28.28 | J2: 56 | K2: 95.72 | M2: 1567 | N2: 0 | O2: 26.4 | P2: 64 | Q2: 97.3333 | S2: 1568 | T2: 0 | U2: 30.8056 | V2: 73 | W2: 101.25 | Y2: 1569 | Z2: 0 | AA2: 18.4419 | AB2: 90 | AC2: 98.907 | AE2: 1570 | AF2: 0 | AG2: 30.8571 | AH2: 74 | AI2: 100.3333 | AK2: 1571 | AL2: 0 | AM2: 33.7143 | AN2: 73 | AO2: 115.3571 | AQ2: 1572 | AR2: 0 | AS2: 25.3778 | AT2: 80 | AU2: 100.4889 | AW2: 1573 | AX2: 0 | AY2: 27.4167 | AZ2: 58 | BA2: 69.1667 | BC2: 1574 | BD2: 0 | BE2: 17.8 | BF2: 55 | BG2: 67 | BI2: 1575 | BJ2: 0 | BK2: 19.4595 | BL2: 74 | BM2: 98.8108 | BO2: 1576 | BP2: 0 | BQ2: 27.7105 | BR2: 76 | BS2: 114.2895 | BU2: 1577 | BV2: 0 | BW2: 22.65 | BX2: 66 | BY2: 84.35 | CA2: 1578 | CB2: 0 | CC2: 19.5111 | CD2: 78 | CE2: 84.2444
B3: 1 | C3: 21.2105 | D3: 64 | E3: 97.5 | H3: 1 | I3: 28.2 | J3: 57 | K3: 96.48 | N3: 1 | O3: 27.1333 | P3: 65 | Q3: 97.4333 | T3: 1 | U3: 31.5 | V3: 74 | W3: 100.9722 | Z3: 1 | AA3: 19.1628 | AB3: 91 | AC3: 98.8372 | AF3: 1 | AG3: 31.2381 | AH3: 75 | AI3: 100.0952 | AL3: 1 | AM3: 34.1786 | AN3: 74 | AO3: 115.6071 | AR3: 1 | AS3: 25.7111 | AT3: 81 | AU3: 100.2889 | AX3: 1 | AY3: 28.3333 | AZ3: 59 | BA3: 69.5 | BD3: 1 | BE3: 18.1667 | BF3: 56 | BG3: 66.4667 | BJ3: 1 | BK3: 20.4595 | BL3: 75 | BM3: 99.1892 | BP3: 1 | BQ3: 28.0789 | BR3: 77 | BS3: 110.9474 | BV3: 1 | BW3: 23.275 | BX3: 67 | BY3: 84.55 | CB3: 1 | CC3: 20.0222 | CD3: 79 | CE3: 84.4444
B4: 2 | C4: 22.3684 | D4: 65 | E4: 95.6053 | H4: 2 | I4: 28.48 | J4: 58 | K4: 97.96 | N4: 2 | O4: 27.4333 | P4: 66 | Q4: 97.5 | T4: 2 | U4: 32.3056 | V4: 75 | W4: 100.2222 | Z4: 2 | AA4: 20.0698 | AB4: 92 | AC4: 97.8837 | AF4: 2 | AG4: 31.2381 | AH4: 76 | AI4: 100.1429 | AL4: 2 | AM4: 34.4286 | AN4: 75 | AO4: 115.7143 | AR4: 2 | AS4: 26.0889 | AT4: 82 | AU4: 100.2444 | AX4: 2 | AY4: 29.0417 | AZ4: 60 | BA4: 69.7917 | BD4: 2 | BE4: 18.4 | BF4: 57 | BG4: 66.2333 | BJ4: 2 | BK4: 21.1892 | BL4: 76 | BM4: 99.1622 | BP4: 2 | BQ4: 28.5 | BR4: 78 | BS4: 103.0263 | BV4: 2 | BW4: 23.825 | BX4: 68 | BY4: 84.8 | CB4: 2 | CC4: 20.3333 | CD4: 80 | CE4: 85.1333
B5: 3 | C5: 23.4474 | D5: 66 | E5: 94.8947 | H5: 3 | I5: 28.84 | J5: 59 | K5: 98.68 | N5: 3 | O5: 27.6667 | P5: 67 | Q5: 98.1667 | T5: 3 | U5: 32.7778 | V5: 76 | W5: 99.5278 | Z5: 3 | AA5: 20.093 | AB5: 93 | AC5: 97.0465 | AF5: 3 | AG5: 31.3095 | AH5: 77 | AI5: 100.0238 | AL5: 3 | AM5: 34.6071 | AN5: 76 | AO5: 115.1071 | AR5: 3 | AS5: 26.1556 | AT5: 83 | AU5: 100.2 | AX5: 3 | AY5: 29.0833 | AZ5: 61 | BA5: 70.0833 | BD5: 3 | BE5: 18.9667 | BF5: 58 | BG5: 66.4667 | BJ5: 3 | BK5: 21.6216 | BL5: 77 | BM5: 98.9459 | BP5: 3 | BQ5: 29.0789 | BR5: 79 | BS5: 94.2895 | BV5: 3 | BW5: 24.425 | BX5: 69 | BY5: 84.95 | CB5: 3 | CC5: 21.1333 | CD5: 81 | CE5: 85.6
B6: 4 | C6: 23.9474 | D6: 67 | E6: 95.4211 | H6: 4 | I6: 29.16 | J6: 60 | K6: 98.16 | N6: 4 | O6: 28.2333 | P6: 68 | Q6: 98.7 | T6: 4 | U6: 33.1389 | V6: 77 | W6: 98.8611 | Z6: 4 | AA6: 21.0698 | AB6: 94 | AC6: 96.0465 | AF6: 4 | AG6: 31.5476 | AH6: 78 | AI6: 99.4286 | AL6: 4 | AM6: 35 | AN6: 77 | AO6: 114.8929 | AR6: 4 | AS6: 26.3778 | AT6: 84 | AU6: 99.4444 | AX6: 4 | AY6: 29.0417 | AZ6: 62 | BA6: 69.7917 | BD6: 4 | BE6: 19.7667 | BF6: 59 | BG6: 66.5333 | BJ6: 4 | BK6: 22.4324 | BL6: 78 | BM6: 98.7568 | BP6: 4 | BQ6: 29.2632 | BR6: 80 | BS6: 89.5526 | BV6: 4 | BW6: 25.225 | BX6: 70 | BY6: 85.375 | CB6: 4 | CC6: 22.3333 | CD6: 82 | CE6: 85
B7: 5 | C7: 24.4211 | D7: 68 | E7: 96.1842 | H7: 5 | I7: 29.52 | J7: 61 | K7: 97.68 | N7: 5 | O7: 29.1333 | P7: 69 | Q7: 98.7333 | T7: 5 | U7: 33.75 | V7: 78 | W7: 98.4167 | Z7: 5 | AA7: 21.7907 | AB7: 95 | AC7: 96.0698 | AF7: 5 | AG7: 31.4762 | AH7: 79 | AI7: 98.3095 | AL7: 5 | AM7: 35.4643 | AN7: 78 | AO7: 114.1429 | AR7: 5 | AS7: 26.6 | AT7: 85 | AU7: 98.2667 | AX7: 5 | AY7: 28.9167 | AZ7: 63 | BA7: 69.9583 | BD7: 5 | BE7: 20.4667 | BF7: 60 | BG7: 65.8 | BJ7: 5 | BK7: 23.3784 | BL7: 79 | BM7: 98.8108 | BP7: 5 | BQ7: 29.5 | BR7: 81 | BS7: 88.9737 | BV7: 5 | BW7: 25.8 | BX7: 71 | BY7: 85.9 | CB7: 5 | CC7: 23.8889 | CD7: 83 | CE7: 83.6444
B8: 6 | C8: 24.7895 | D8: 69 | E8: 96.5 | H8: 6 | I8: 29.48 | J8: 62 | K8: 96.8 | N8: 6 | O8: 29.6333 | P8: 70 | Q8: 98.9 | T8: 6 | U8: 34.3056 | V8: 79 | W8: 97.9722 | Z8: 6 | AA8: 23.0465 | AB8: 96 | AC8: 95.6977 | AF8: 6 | AG8: 31.6905 | AH8: 80 | AI8: 97.6905 | AL8: 6 | AM8: 35.9643 | AN8: 79 | AO8: 112.4286 | AR8: 6 | AS8: 26.9333 | AT8: 86 | AU8: 96.9778 | AX8: 6 | AY8: 29 | AZ8: 64 | BA8: 70.375 | BD8: 6 | BE8: 20.9667 | BF8: 61 | BG8: 64.3667 | BJ8: 6 | BK8: 24.4595 | BL8: 80 | BM8: 98.4054 | BP8: 6 | BQ8: 29.4474 | BR8: 82 | BS8: 90.2368 | BV8: 6 | BW8: 26.725 | BX8: 72 | BY8: 85.8 | CB8: 6 | CC8: 25.0889 | CD8: 84 | CE8: 82.7111
B9: 7 | C9: 25.3947 | D9: 70 | E9: 96.3947 | H9: 7 | I9: 29.8 | J9: 63 | K9: 95.84 | N9: 7 | O9: 30.2667 | P9: 71 | Q9: 98.8 | T9: 7 | U9: 34.5833 | V9: 80 | W9: 97.6944 | Z9: 7 | AA9: 24.3721 | AB9: 97 | AC9: 94.6279 | AF9: 7 | AG9: 32.1429 | AH9: 81 | AI9: 97.2857 | AL9: 7 | AM9: 36.4643 | AN9: 80 | AO9: 110.1429 | AR9: 7 | AS9: 27.5333 | AT9: 87 | AU9: 95.5111 | AX9: 7 | AY9: 28.9583 | AZ9: 65 | BA9: 70.0833 | BD9: 7 | BE9: 20.5333 | BF9: 62 | BG9: 62.8333 | BJ9: 7 | BK9: 25.3243 | BL9: 81 | BM9: 98 | BP9: 7 | BQ9: 29.3947 | BR9: 83 | BS9: 92.1842 | BV9: 7 | BW9: 27.725 | BX9: 73 | BY9: 85.65 | CB9: 7 | CC9: 25.9556 | CD9: 85 | CE9: 82.2444
B10: 8 | C10: 25.6053 | D10: 71 | E10: 96.6053 | H10: 8 | I10: 30.24 | J10: 64 | K10: 94.24 | N10: 8 | O10: 30.7333 | P10: 72 | Q10: 98.6667 | T10: 8 | U10: 35.5556 | V10: 81 | W10: 98.0833 | Z10: 8 | AA10: 25.0465 | AB10: 98 | AC10: 93.2558 | AF10: 8 | AG10: 32.4048 | AH10: 82 | AI10: 97.2619 | AL10: 8 | AM10: 37.3214 | AN10: 81 | AO10: 108.25 | AR10: 8 | AS10: 27.3778 | AT10: 88 | AU10: 94.4444 | AX10: 8 | AY10: 30.2083 | AZ10: 66 | BA10: 69.7083 | BD10: 8 | BE10: 20.1 | BF10: 63 | BG10: 61.4 | BJ10: 8 | BK10: 25.5676 | BL10: 82 | BM10: 97.8108 | BP10: 8 | BQ10: 29.3947 | BR10: 84 | BS10: 94 | BV10: 8 | BW10: 28.675 | BX10: 74 | BY10: 85.5 | CB10: 8 | CC10: 25.8444 | CD10: 86 | CE10: 81.9333
B11: 9 | C11: 25.7895 | D11: 72 | E11: 96.9737 | H11: 9 | I11: 30.88 | J11: 65 | K11: 92.48 | N11: 9 | O11: 30.9 | P11: 73 | Q11: 98.3 | T11: 9 | U11: 37 | V11: 82 | W11: 98.5556 | Z11: 9 | AA11: 26.1395 | AB11: 99 | AC11: 92.8372 | AF11: 9 | AG11: 33.0714 | AH11: 83 | AI11: 97.1429 | AL11: 9 | AM11: 38.0357 | AN11: 82 | AO11: 108.0714 | AR11: 9 | AS11: 27.4222 | AT11: 89 | AU11: 94.4889 | AX11: 9 | AY11: 31.7917 | AZ11: 67 | BA11: 69.7917 | BD11: 9 | BE11: 20.2667 | BF11: 64 | BG11: 59.4 | BJ11: 9 | BK11: 26.3514 | BL11: 83 | BM11: 97.3784 | BP11: 9 | BQ11: 29.2895 | BR11: 85 | BS11: 94.3684 | BV11: 9 | BW11: 29.1 | BX11: 75 | BY11: 85.775 | CB11: 9 | CC11: 25.6222 | CD11: 87 | CE11: 81.0667
B12: 10 | C12: 26.9211 | D12: 73 | E12: 97.1316 | H12: 10 | I12: 31.08 | J12: 66 | K12: 90.72 | N12: 10 | O12: 30.4667 | P12: 74 | Q12: 97.8333 | T12: 10 | U12: 38.3611 | V12: 83 | W12: 98.8889 | Z12: 10 | AA12: 26.3953 | AB12: 100 | AC12: 92.7674 | AF12: 10 | AG12: 33.8095 | AH12: 84 | AI12: 96.7143 | AL12: 10 | AM12: 39.1786 | AN12: 83 | AO12: 108.3571 | AR12: 10 | AS12: 28 | AT12: 90 | AU12: 94.4667 | AX12: 10 | AY12: 32.625 | AZ12: 68 | BA12: 69.3333 | BD12: 10 | BE12: 20.7 | BF12: 65 | BG12: 56.6333 | BJ12: 10 | BK12: 26.9189 | BL12: 84 | BM12: 97.027 | BP12: 10 | BQ12: 29.5526 | BR12: 86 | BS12: 93.4474 | BV12: 10 | BW12: 29.55 | BX12: 76 | BY12: 86.4 | CB12: 10 | CC12: 26.3556 | CD12: 88 | CE12: 80.7333
B13: 11 | C13: 29.1053 | D13: 74 | E13: 97.3421 | H13: 11 | I13: 31.76 | J13: 67 | K13: 88.6 | N13: 11 | O13: 30.3667 | P13: 75 | Q13: 97.6667 | T13: 11 | U13: 38.3333 | V13: 84 | W13: 98.6389 | Z13: 11 | AA13: 26.7442 | AB13: 101 | AC13: 93.2791 | AF13: 11 | AG13: 34.1667 | AH13: 85 | AI13: 96.1429 | AL13: 11 | AM13: 40.3571 | AN13: 84 | AO13: 108.2857 | AR13: 11 | AS13: 29.4889 | AT13: 91 | AU13: 93.5111 | AX13: 11 | AY13: 32.8333 | AZ13: 69 | BA13: 68 | BD13: 11 | BE13: 21.6 | BF13: 66 | BG13: 53.9333 | BJ13: 11 | BK13: 27.5135 | BL13: 85 | BM13: 96.7568 | BP13: 11 | BQ13: 30 | BR13: 87 | BS13: 91.9474 | BV13: 11 | BW13: 30.025 | BX13: 77 | BY13: 86.9 | CB13: 11 | CC13: 27.3778 | CD13: 89 | CE13: 80.0222
B14: 12 | C14: 32.0526 | D14: 75 | E14: 97.0789 | H14: 12 | I14: 32.6 | J14: 68 | K14: 85.4 | N14: 12 | O14: 31.0667 | P14: 76 | Q14: 96.7667 | T14: 12 | U14: 38.6111 | V14: 85 | W14: 98.2222 | Z14: 12 | AA14: 26.7442 | AB14: 102 | AC14: 92.8837 | AF14: 12 | AG14: 34.7619 | AH14: 86 | AI14: 95.6667 | AL14: 12 | AM14: 40.75 | AN14: 85 | AO14: 108.4286 | AR14: 12 | AS14: 31.0222 | AT14: 92 | AU14: 93.1778 | AX14: 12 | AY14: 33.625 | AZ14: 70 | BA14: 65.7083 | BD14: 12 | BE14: 22.1 | BF14: 67 | BG14: 51.8333 | BJ14: 12 | BK14: 28.1622 | BL14: 86 | BM14: 96.6487 | BP14: 12 | BQ14: 30.5526 | BR14: 88 | BS14: 89.8947 | BV14: 12 | BW14: 30.175 | BX14: 78 | BY14: 86.625 | CB14: 12 | CC14: 27.6889 | CD14: 90 | CE14: 79.1778
... B56: 54 | C56: 94.1579 | D56: 117 | E56: 28.2632 | H56: 54 | I56: 94.4 | J56: 110 | K56: 25.84 | N56: 54 | O56: 95.2667 | P56: 118 | Q56: 32.2667 | T56: 54 | U56: 93.9167 | V56: 127 | W56: 40.75 | Z56: 54 | AA56: 61.3488 | AB56: 144 | AC56: 36.7442 | AF56: 54 | AG56: 79.5238 | AH56: 128 | AI56: 43.3333 | AL56: 54 | AM56: 84.2857 | AN56: 127 | AO56: 45.0357 | AR56: 54 | AS56: 82 | AT56: 134 | AU56: 42.4 | AX56: 54 | AY56: 68.7083 | AZ56: 112 | BA56: 31.0417 | BD56: 54 | BE56: 67.6333 | BF56: 109 | BG56: 19.2333 | BJ56: 54 | BK56: 92.6216 | BL56: 128 | BM56: 29 | BP56: 54 | BQ56: 95.4737 | BR56: 130 | BS56: 32.7895 | BV56: 54 | BW56: 79.2 | BX56: 120 | BY56: 33.825 | CB56: 54 | CC56: 81.2444 | CD56: 132 | CE56: 30.1111
B57: 55 | C57: 93.7368 | D57: 118 | E57: 27.2895 | H57: 55 | I57: 94.96 | J57: 111 | K57: 25.56 | N57: 55 | O57: 96.6333 | P57: 119 | Q57: 32.0667 | T57: 55 | U57: 96.0278 | V57: 128 | W57: 40.6944 | Z57: 55 | AA57: 62.2093 | AB57: 145 | AC57: 35.6279 | AF57: 55 | AG57: 81.119 | AH57: 129 | AI57: 43 | AL57: 55 | AM57: 86.3571 | AN57: 128 | AO57: 43.6429 | AR57: 55 | AS57: 86.0889 | AT57: 135 | AU57: 41.7111 | AX57: 55 | AY57: 68.7917 | AZ57: 113 | BA57: 30.5417 | BJ57: 55 | BK57: 93.1351 | BL57: 129 | BM57: 28.8649 | BP57: 55 | BQ57: 91 | BR57: 131 | BS57: 32.1316 | BV57: 55 | BW57: 80.1 | BX57: 121 | BY57: 32.775 | CB57: 55 | CC57: 82.6667 | CD57: 133 | CE57: 29.9778
B58: 56 | C58: 93.9211 | D58: 119 | E58: 25.2105 | N58: 56 | O58: 97.3333 | P58: 120 | Q58: 31.7667 | T58: 56 | U58: 97.0278 | V58: 129 | W58: 40.4167 | Z58: 56 | AA58: 62.5581 | AB58: 146 | AC58: 36.6279 | AF58: 56 | AG58: 83.1667 | AH58: 130 | AI58: 42.3333 | AL58: 56 | AM58: 88.5357 | AN58: 129 | AO58: 42.3571 | AR58: 56 | AS58: 89.7333 | AT58: 136 | AU58: 41.4222 | AX58: 56 | AY58: 69.2917 | AZ58: 114 | BA58: 30.0417 | BJ58: 56 | BK58: 93.4324 | BL58: 130 | BM58: 28.6216 | BP58: 56 | BQ58: 88.8947 | BR58: 132 | BS58: 32.0263 | BV58: 56 | BW58: 81.125 | BX58: 122 | BY58: 31.975 | CB58: 56 | CC58: 83.5111 | CD58: 134 | CE58: 29.2
B59: 57 | C59: 95.0789 | D59: 120 | E59: 23.5263 | N59: 57 | O59: 97.1 | P59: 121 | Q59: 31.2667 | T59: 57 | U59: 98.3056 | V59: 130 | W59: 39.2222 | Z59: 57 | AA59: 63 | AB59: 147 | AC59: 36.3256 | AF59: 57 | AG59: 86.1429 | AH59: 131 | AI59: 41.5476 | AL59: 57 | AM59: 91.2143 | AN59: 130 | AO59: 41.1071 | AR59: 57 | AS59: 92.4889 | AT59: 137 | AU59: 40.5778 | AX59: 57 | AY59: 69.2917 | AZ59: 115 | BA59: 29.2917 | BJ59: 57 | BK59: 93.4054 | BL59: 131 | BM59: 28.0541 | BP59: 57 | BQ59: 87.2632 | BR59: 133 | BS59: 32.1316 | BV59: 57 | BW59: 82.4 | BX59: 123 | BY59: 31.525 | CB59: 57 | CC59: 84.5333 | CD59: 135 | CE59: 28.1778
B60: 58 | C60: 96.4211 | D60: 121 | E60: 22.6316 | N60: 58 | O60: 96.7667 | P60: 122 | Q60: 30.6667 | T60: 58 | U60: 100.25 | V60: 131 | W60: 38.2222 | Z60: 58 | AA60: 63.2093 | AB60: 148 | AC60: 36.0233 | AF60: 58 | AG60: 88.9048 | AH60: 132 | AI60: 40.5714 | AL60: 58 | AM60: 94.3214 | AN60: 131 | AO60: 40.2143 | AR60: 58 | AS60: 93.1778 | AT60: 138 | AU60: 39 | BJ60: 58 | BK60: 93.4324 | BL60: 132 | BM60: 27.5405 | BP60: 58 | BQ60: 85.9211 | BR60: 134 | BS60: 32.1316 | BV60: 58 | BW60: 83.425 | BX60: 124 | BY60: 30.825 | CB60: 58 | CC60: 86.2 | CD60: 136 | CE60: 27.4667
B61: 59 | C61: 97.5789 | D61: 122 | E61: 22.3421 | N61: 59 | O61: 97 | P61: 123 | Q61: 30.4667 | T61: 59 | U61: 102.3056 | V61: 132 | W61: 37.1111 | Z61: 59 | AA61: 63.0698 | AB61: 149 | AC61: 36.1628 | AF61: 59 | AG61: 91.6905 | AH61: 133 | AI61: 39.7619 | AL61: 59 | AM61: 97.1429 | AN61: 132 | AO61: 39.7857 | AR61: 59 | AS61: 93.0444 | AT61: 139 | AU61: 37.2667 | BJ61: 59 | BK61: 93.7297 | BL61: 133 | BM61: 26.8108 | BP61: 59 | BQ61: 86.8684 | BR61: 135 | BS61: 31.8947 | BV61: 59 | BW61: 84.25 | BX61: 125 | BY61: 30.2 | CB61: 59 | CC61: 87.0444 | CD61: 137 | CE61: 26.8889
B62: 60 | C62: 97.9474 | D62: 123 | E62: 21.6053 | N62: 60 | O62: 97.6333 | P62: 124 | Q62: 30.6 | T62: 60 | U62: 102.8611 | V62: 133 | W62: 36.8333 | Z62: 60 | AA62: 63.3256 | AB62: 150 | AC62: 35.8372 | AF62: 60 | AG62: 93.4762 | AH62: 134 | AI62: 39.119 | AL62: 60 | AM62: 100.1786 | AN62: 133 | AO62: 39.3929 | AR62: 60 | AS62: 92.8667 | AT62: 140 | AU62: 36.3778 | BJ62: 60 | BK62: 94.3243 | BL62: 134 | BM62: 25.9189 | BP62: 60 | BQ62: 88.1842 | BR62: 136 | BS62: 31.2368 | BV62: 60 | BW62: 84.35 | BX62: 126 | BY62: 29.625 | CB62: 60 | CC62: 87.1111 | CD62: 138 | CE62: 26.3778
B63: 61 | C63: 98.2368 | D63: 124 | E63: 20.1842 | N63: 61 | O63: 97.9 | P63: 125 | Q63: 29.9333 | T63: 61 | U63: 102.9444 | V63: 134 | W63: 36.5 | Z63: 61 | AA63: 64.4884 | AB63: 151 | AC63: 34.6977 | AF63: 61 | AG63: 94.5714 | AH63: 135 | AI63: 38.9524 | AL63: 61 | AM63: 103.1429 | AN63: 134 | AO63: 38.25 | AR63: 61 | AS63: 92.9333 | AT63: 141 | AU63: 35.4667 | BJ63: 61 | BK63: 94.9189 | BL63: 135 | BM63: 25.2973 | BP63: 61 | BQ63: 88.7895 | BR63: 137 | BS63: 30.4737 | BV63: 61 | BW63: 84.55 | BX63: 127 | BY63: 29.225 | CB63: 61 | CC63: 87.6444 | CD63: 139 | CE63: 25.2889
B64: 62 | C64: 98.5263 | D64: 125 | E64: 19.1316 | N64: 62 | O64: 97.9667 | P64: 126 | Q64: 29.3333 | T64: 62 | U64: 103.2222 | V64: 135 | W64: 35.6944 | Z64: 62 | AA64: 65.6977 | AB64: 152 | AC64: 32.907 | AF64: 62 | AG64: 95.7857 | AH64: 136 | AI64: 38.4048 | AL64: 62 | AM64: 105.5714 | AN64: 135 | AO64: 37.1786 | AR64: 62 | AS64: 92.9333 | AT64: 142 | AU64: 34.9556 | BJ64: 62 | BK64: 94.9459 | BL64: 136 | BM64: 24.3514 | BP64: 62 | BQ64: 91.6316 | BR64: 138 | BS64: 30.0789 | BV64: 62 | BW64: 84.65 | BX64: 128 | BY64: 28.775 | CB64: 62 | CC64: 87.8889 | CD64: 140 | CE64: 24.3778
N65: 63 | O65: 97.7667 | P65: 127 | Q65: 29.0333 | T65: 63 | U65: 103.25 | V65: 136 | W65: 34.6667 | Z65: 63 | AA65: 66.814 | AB65: 153 | AC65: 30.9535 | AF65: 63 | AG65: 96.9048 | AH65: 137 | AI65: 38.2619 | AL65: 63 | AM65: 107.6786 | AN65: 136 | AO65: 36.5357 | AR65: 63 | AS65: 93.2 | AT65: 143 | AU65: 34.4889 | BJ65: 63 | BK65: 95.1081 | BL65: 137 | BM65: 23.4595 | BP65: 63 | BQ65: 97.2632 | BR65: 139 | BS65: 29.9211 | BV65: 63 | BW65: 84.525 | BX65: 129 | BY65: 28.625 | CB65: 63 | CC65: 87.6 | CD65: 141 | CE65: 23.8667
T66: 64 | U66: 103.1389 | V66: 137 | W66: 34.0556 | Z66: 64 | AA66: 67.7907 | AB66: 154 | AC66: 29.5581 | AF66: 64 | AG66: 97.7619 | AH66: 138 | AI66: 37.5952 | AL66: 64 | AM66: 110.0357 | AN66: 137 | AO66: 36.4643 | AR66: 64 | AS66: 94.1333 | AT66: 144 | AU66: 34.1333 | BJ66: 64 | BK66: 95.3513 | BL66: 138 | BM66: 22.9459 | BP66: 64 | BQ66: 102.8684 | BR66: 140 | BS66: 29.6316 | BV66: 64 | BW66: 84.475 | BX66: 130 | BY66: 28.75 | CB66: 64 | CC66: 87.4 | CD66: 142 | CE66: 23.3111
T67: 65 | U67: 103.0833 | V67: 138 | W67: 33.8889 | Z67: 65 | AA67: 69.7442 | AB67: 155 | AC67: 29.4186 | AF67: 65 | AG67: 98.0952 | AH67: 139 | AI67: 37.0714 | AL67: 65 | AM67: 111.3214 | AN67: 138 | AO67: 36.5714 | AR67: 65 | AS67: 95.2 | AT67: 145 | AU67: 33.7333 | BJ67: 65 | BK67: 95.3784 | BL67: 139 | BM67: 22.4865 | BP67: 65 | BQ67: 106.2895 | BR67: 141 | BS67: 29.3684 | BV67: 65 | BW67: 84.175 | BX67: 131 | BY67: 28.725 | CB67: 65 | CC67: 87.4222 | CD67: 143 | CE67: 22.3111
T68: 66 | U68: 103.2222 | V68: 139 | W68: 33.5278 | Z68: 66 | AA68: 72.4186 | AB68: 156 | AC68: 29.6047 | AF68: 66 | AG68: 98.4286 | AH68: 140 | AI68: 36.3095 | AL68: 66 | AM68: 111.2857 | AN68: 139 | AO68: 36.8929 | AR68: 66 | AS68: 96.5556 | AT68: 146 | AU68: 33.6889 | BJ68: 66 | BK68: 95.7027 | BL68: 140 | BM68: 21.973 | BP68: 66 | BQ68: 108.0789 | BR68: 142 | BS68: 29.3158 | CB68: 66 | CC68: 87.3333 | CD68: 144 | CE68: 21.8889
T69: 67 | U69: 102.8333 | V69: 140 | W69: 33.3889 | Z69: 67 | AA69: 74.4651 | AB69: 157 | AC69: 29.8837 | AF69: 67 | AG69: 98.7619 | AH69: 141 | AI69: 35.381 | AL69: 67 | AM69: 110.8929 | AN69: 140 | AO69: 36.7857 | AR69: 67 | AS69: 97.6444 | AT69: 147 | AU69: 33.8 | BJ69: 67 | BK69: 96.1892 | BL69: 141 | BM69: 21.4054 | BP69: 67 | BQ69: 108.6842 | BR69: 143 | BS69: 29.2895 | CB69: 67 | CC69: 87.1111 | CD69: 145 | CE69: 21.4
T70: 68 | U70: 102.6111 | V70: 141 | W70: 33.1667 | Z70: 68 | AA70: 76.4419 | AB70: 158 | AC70: 30.2558 | AF70: 68 | AG70: 98.9048 | AH70: 142 | AI70: 34.5476 | AL70: 68 | AM70: 111.4286 | AN70: 141 | AO70: 36.2857 | AR70: 68 | AS70: 98.6889 | AT70: 148 | AU70: 33.4 | BJ70: 68 | BK70: 96.3513 | BL70: 142 | BM70: 20.8378 | BP70: 68 | BQ70: 108 | BR70: 144 | BS70: 29.1579 | CB70: 68 | CC70: 87.3111 | CD70: 146 | CE70: 20.7778
T71: 69 | U71: 102.5556 | V71: 142 | W71: 33.0556 | Z71: 69 | AA71: 78.3023 | AB71: 159 | AC71: 30.0465 | AF71: 69 | AG71: 99 | AH71: 143 | AI71: 33.8333 | AL71: 69 | AM71: 112.3214 | AN71: 142 | AO71: 35.1786 | AR71: 69 | AS71: 99.2444 | AT71: 149 | AU71: 32.3333 | BJ71: 69 | BK71: 96.4865 | BL71: 143 | BM71: 20.4324 | BP71: 69 | BQ71: 106.4737 | BR71: 145 | BS71: 29.1842 | CB71: 69 | CC71: 87.4444 | CD71: 147 | CE71: 20.5333
T72: 70 | U72: 102.4167 | V72: 143 | W72: 33 | Z72: 70 | AA72: 82.0465 | AB72: 160 | AC72: 29 | AF72: 70 | AG72: 99.1667 | AH72: 144 | AI72: 33.381 | AL72: 70 | AM72: 113.1429 | AN72: 143 | AO72: 34.6786 | AR72: 70 | AS72: 99.0444 | AT72: 150 | AU72: 31.1778 | BJ72: 70 | BK72: 96.973 | BL72: 144 | BM72: 20.2703 | BP72: 70 | BQ72: 105.6842 | BR72: 146 | BS72: 28.6053 | CB72: 70 | CC72: 87.2 | CD72: 148 | CE72: 19.9333
T73: 71 | U73: 102.4722 | V73: 144 | W73: 32.6667 | Z73: 71 | AA73: 84.6744 | AB73: 161 | AC73: 27.7907 | AF73: 71 | AG73: 99.619 | AH73: 145 | AI73: 33.119 | AL73: 71 | AM73: 113.4286 | AN73: 144 | AO73: 34.3929 | AR73: 71 | AS73: 98.5333 | AT73: 151 | AU73: 30.2889 | BJ73: 71 | BK73: 97.4324 | BL73: 145 | BM73: 20.0541 | BP73: 71 | BQ73: 106.1316 | BR73: 147 | BS73: 27.9211 | CB73: 71 | CC73: 86.9111 | CD73: 149 | CE73: 19.4889
T74: 72 | U74: 101.9167 | V74: 145 | W74: 31.9722 | Z74: 72 | AA74: 86.2326 | AB74: 162 | AC74: 27.3023 | AF74: 72 | AG74: 100.0238 | AH74: 146 | AI74: 32.5476 | AL74: 72 | AM74: 114.3929 | AN74: 145 | AO74: 33.9286 | AR74: 72 | AS74: 98.2889 | AT74: 152 | AU74: 29.3556 | BJ74: 72 | BK74: 97.6757 | BL74: 146 | BM74: 19.8919 | BP74: 72 | BQ74: 106.8158 | BR74: 148 | BS74: 27.5526 | CB74: 72 | CC74: 86.6444 | CD74: 150 | CE74: 19.2667
Z75: 73 | AA75: 87.8372 | AB75: 163 | AC75: 27.1163 | AF75: 73 | AG75: 100.2381 | AH75: 147 | AI75: 31.9762 | AR75: 73 | AS75: 98.1556 | AT75: 153 | AU75: 29.4222 | BJ75: 73 | BK75: 98.2432 | BL75: 147 | BM75: 19.1892 | BP75: 73 | BQ75: 108.5526 | BR75: 149 | BS75: 27.5 | CB75: 73 | CC75: 86.1778 | CD75: 151 | CE75: 18.9778
Z76: 74 | AA76: 89.8605 | AB76: 164 | AC76: 26.6744 | AR76: 74 | AS76: 98.2889 | AT76: 154 | AU76: 29.9333 | BP76: 74 | BQ76: 111.0263 | BR76: 150 | BS76: 27.3947 | CB76: 74 | CC76: 85.5778 | CD76: 152 | CE76: 18.7556
Z77: 75 | AA77: 91.6279 | AB77: 165 | AC77: 26 | AR77: 75 | AS77: 98.8 | AT77: 155 | AU77: 29.9333 | BP77: 75 | BQ77: 113.2368 | BR77: 151 | BS77: 26.8947 | CB77: 75 | CC77: 85.1556 | CD77: 153 | CE77: 18.3333
Z78: 76 | AA78: 92.907 | AB78: 166 | AC78: 24.9767 | AR78: 76 | AS78: 99.4667 | AT78: 156 | AU78: 29.6889 | CB78: 76 | CC78: 84.7556 | CD78: 154 | CE78: 17.9556
Z79: 77 | AA79: 94.4186 | AB79: 167 | AC79: 23.907 | AR79: 77 | AS79: 99.8444 | AT79: 157 | AU79: 29.4444 | CB79: 77 | CC79: 84.5333 | CD79: 155 | CE79: 17.8667
Z80: 78 | AA80: 96.6279 | AB80: 168 | AC80: 23.0698 | AR80: 78 | AS80: 100.6 | AT80: 158 | AU80: 29.3111
Z81: 79 | AA81: 98.2326 | AB81: 169 | AC81: 22.3488 | AR81: 79 | AS81: 100.7556 | AT81: 159 | AU81: 28.5778
...

Sheet data_analysis
A1: Control | B1: Image_ID | C1: L AVG | D1: L SUM | E1: R AVG | F1: R SUM | H1: B3A | I1: Image_ID | J1: L AVG | K1: L SUM | L1: R AVG | M1: R SUM
B2: 1580 | C2: =AVERAGE(raw_con!$CO$2:$CO$69) -> 60.982278 | D2: =SUM(raw_con!$CO$2:$CO$69) -> 4146.7949 | E2: =AVERAGE(raw_con!$E$2:$E$81) -> 62.705261 | F2: =SUM(raw_con!$E$2:$E$81) -> 5016.4209
B3: 1581 | C3: =AVERAGE(raw_con!$I$2:$I$58) -> 52.059063 | D3: =SUM(raw_con!$I$2:$I$58) -> 2967.3666 | E3: =AVERAGE(raw_con!$K$2:$K$58) -> 53.780121 | F3: =SUM(raw_con!$K$2:$K$58) -> 3065.4669
B4: 1582 | C4: =AVERAGE(raw_con!$O$2:$O$73) -> 59.013076 | D4: =SUM(raw_con!$O$2:$O$73) -> 4248.9415 | E4: =AVERAGE(raw_con!$Q$2:$Q$73) -> 63.827208 | F4: =SUM(raw_con!$Q$2:$Q$73) -> 4595.559
B5: 1583 | C5: =AVERAGE(raw_con!$U$2:$U$63) -> 67.859544 | D5: =SUM(raw_con!$U$2:$U$63) -> 4207.2917 | E5: =AVERAGE(raw_con!$W$2:$W$63) -> 63.502694 | F5: =SUM(raw_con!$W$2:$W$63) -> 3937.167
B6: 1585 | C6: =AVERAGE(raw_con!$AA$2:$AA$71) -> 57.215813 | D6: =SUM(raw_con!$AA$2:$AA$71) -> 4005.1069 | E6: =AVERAGE(raw_con!$AC$2:$AC$71) -> 65.066333 | F6: =SUM(raw_con!$AC$2:$AC$71) -> 4554.6433
B7: 1586 | C7: =AVERAGE(raw_con!$AG$2:$AG$68) -> 55.068228 | D7: =SUM(raw_con!$AG$2:$AG$68) -> 3689.5713 | E7: =AVERAGE(raw_con!$AI$2:$AI$68) -> 58.688164 | F7: =SUM(raw_con!$AI$2:$AI$68) -> 3932.107
B8: 1587 | C8: =AVERAGE(raw_con!$AM$2:$AM$73) -> 48.994444 | D8: =SUM(raw_con!$AM$2:$AM$73) -> 3527.6 | E8: =AVERAGE(raw_con!$AO$2:$AO$73) -> 60.850928 | F8: =SUM(raw_con!$AO$2:$AO$73) -> 4381.2668
B9: 1588 | C9: =AVERAGE(raw_con!$AS$2:$AS$55) -> 57.726048 | D9: =SUM(raw_con!$AS$2:$AS$55) -> 3117.2066 | E9: =AVERAGE(raw_con!$AU$2:$AU$55) -> 60.825028 | F9: =SUM(raw_con!$AU$2:$AU$55) -> 3284.5515
B10: 1589 | C10: =AVERAGE(raw_con!$AY$2:$AY$70) -> 47.057371 | D10: =SUM(raw_con!$AY$2:$AY$70) -> 3246.9586 | E10: =AVERAGE(raw_con!$BA$2:$BA$70) -> 45.699278 | F10: =SUM(raw_con!$BA$2:$BA$70) -> 3153.2502
B11: 1590 | C11: =AVERAGE(raw_con!$BE$2:$BE$56) -> 72.43978 | D11: =SUM(raw_con!$BE$2:$BE$56) -> 3984.1879 | E11: =AVERAGE(raw_con!$BG$2:$BG$56) -> 73.465905 | F11: =SUM(raw_con!$BG$2:$BG$56) -> 4040.6248
B12: 1591 | C12: =AVERAGE(raw_con!$BK$2:$BK$62) -> 51.439344 | D12: =SUM(raw_con!$BK$2:$BK$62) -> 3137.8 | E12: =AVERAGE(raw_con!$BM$2:$BM$62) -> 48.061475 | F12: =SUM(raw_con!$BM$2:$BM$62) -> 2931.75
B13: 1592 | C13: =AVERAGE(raw_con!$BQ$2:$BQ$59) -> 67.499995 | D13: =SUM(raw_con!$BQ$2:$BQ$59) -> 3914.9997 | E13: =AVERAGE(raw_con!$BS$2:$BS$59) -> 62.986924 | F13: =SUM(raw_con!$BS$2:$BS$59) -> 3653.2416
B14: 1593 | C14: =AVERAGE(raw_con!$BW$2:$BW$68) -> 66.664858 | D14: =SUM(raw_con!$BW$2:$BW$68) -> 4466.5455 | E14: =AVERAGE(raw_con!$BY$2:$BY$68) -> 58.109451 | F14: =SUM(raw_con!$BY$2:$BY$68) -> 3893.3332
B15: 1594 | C15: =AVERAGE(raw_con!$CC$2:$CC$76) -> 55.818989 | D15: =SUM(raw_con!$CC$2:$CC$76) -> 4186.4242 | E15: =AVERAGE(raw_con!$CE$2:$CE$76) -> 47.151915 | F15: =SUM(raw_con!$CE$2:$CE$76) -> 3536.3936
B16: 1596 | C16: =AVERAGE(raw_con!$CI$2:$CI$78) -> 57.066739 | D16: =SUM(raw_con!$CI$2:$CI$78) -> 4394.1389 | E16: =AVERAGE(raw_con!$CK$2:$CK$78) -> 60.40873 | F16: =SUM(raw_con!$CK$2:$CK$78) -> 4651.4722
B17: 1597 | C17: =AVERAGE(raw_con!CO2:CO69) -> 60.982278 | D17: =SUM(raw_con!CP2:CP69) -> 6902 | E17: =AVERAGE(raw_con!$CQ$2:$CQ$69) -> 55.692315 | F17: =SUM(raw_con!$CQ$2:$CQ$69) -> 3787.0774
B18: 1598 | C18: =AVERAGE(raw_con!$CU$2:$CU$71) -> 55.315513 | D18: =SUM(raw_con!$CU$2:$CU$71) -> 3872.0859 | E18: =AVERAGE(raw_con!$CW$2:$CW$71) -> 50.910613 | F18: =SUM(raw_con!$CW$2:$CW$71) -> 3563.7429
B19: 1599 | C19: =AVERAGE(raw_con!$DA$2:$DA$92) -> 61.252746 | D19: =SUM(raw_con!$DA$2:$DA$92) -> 5573.9999 | E19: =AVERAGE(raw_con!$DC$2:$DC$92) -> 72.050389 | F19: =SUM(raw_con!$DC$2:$DC$92) -> 6556.5854
B20: 1600 | C20: =AVERAGE(raw_con!$DG$2:$DG$78) -> 64.626547 | D20: =SUM(raw_con!$DG$2:$DG$78) -> 4976.2441 | E20: =AVERAGE(raw_con!$DI$2:$DI$78) -> 59.307649 | F20: =SUM(raw_con!$DI$2:$DI$78) -> 4566.689
A22: AVGs | C22: =AVERAGE(C2:C20) -> 58.899087 | D22: =AVERAGE(D2:D20) -> 4135.0139 | E22: =AVERAGE(E2:E20) -> 59.11002 | F22: =AVERAGE(F2:F20) -> 4057.9654
A23: n | B23: =COUNT(B2:B20) -> 19

Sheet old_data_old_method
A1: Control | G1: Bacteria
A2: Image_ID | B2: L (area under curve) | C2: R | D2: ratio | F2: Image_ID | G2: L | H2: R | I2: ratio
A3: 1580 | B3: 30262.986 | C3: =29588.329+168.728 -> 29757.057 | D3: =B3/C3 -> 1.017002 | F3: 1562 | G3: 13447.903 | H3: 10457.924 | I3: =G3/H3 -> 1.2859056
A4: 1581 | B4: 15765.368 | C4: 14395.853 | D4: =B4/C4 -> 1.0951326 | F4: 1566 | G4: 16497.388 | H4: 16162.995 | I4: =G4/H4 -> 1.0206888
A5: 1582 | B5: 28598.886 | C5: =23352.016+96.778+260.607 -> 23709.401 | D5: =B5/C5 -> 1.2062256 | F5: 1567 | G5: 13881.681 | H5: =10635.004+306.435 -> 10941.439 | I5: =G5/H5 -> 1.2687253
A6: 1583 | B6: 27712.43 | C6: =22994.773+454.092 -> 23448.865 | D6: =B6/C6 -> 1.1818239 | F6: 1568 | G6: 29310.966 | H6: 25761.208 | I6: =G6/H6 -> 1.1377947
A7: 1585 | B7: 26868.007 | C7: 27089.421 | D7: =B7/C7 -> 0.99182655 | F7: 1569 | G7: 41684.978 | H7: =37186.057+30.95 -> 37217.007 | I7: =G7/H7 -> 1.1200519
A8: 1586 | B8: 19157.167 | C8: 19518.459 | D8: =B8/C8 -> 0.98148973 | F8: 1570 | G8: 29067.551 | H8: 28582.915 | I8: =G8/H8 -> 1.0169554
A9: 1587 | B9: 38257.815 | C9: 41074.501 | D9: =B9/C9 -> 0.93142495 | F9: 1571 | G9: 24778.723 | H9: 31612.037 | I9: =G9/H9 -> 0.78383823
A10: 1588 | B10: 19280.137 | C10: 18356.409 | D10: =B10/C10 -> 1.0503218 | F10: 1572 | G10: 18319.409 | H10: =17024.338+186.899 -> 17211.237 | I10: =G10/H10 -> 1.0643865
A11: 1589 | B11: 15356.238 | C11: =12498.711+2205.698 -> 14704.409 | D11: =B11/C11 -> 1.0443288 | F11: 1573 | G11: 5346.154 | H11: =6624.234+664.577 -> 7288.811 | I11: =G11/H11 -> 0.73347409
A12: 1590 | B12: 21081.723 | C12: 21437.752 | D12: =B12/C12 -> 0.98339243 | F12: 1574 | G12: 9735.497 | H12: =8379.861+138.607 -> 8518.468 | I12: =G12/H12 -> 1.1428695
A13: 1592 | B13: 25643.158 | C13: =23170.844+32.95 -> 23203.794 | D13: =B13/C13 -> 1.1051278 | F13: 1575 | G13: =10345.64+2562.184 -> 12907.824 | H13: 19158.652 | I13: =G13/H13 -> 0.67373341
A14: 1593 | B14: 33587.401 | C14: =31849.187+26.95 -> 31876.137 | D14: =B14/C14 -> 1.0536848 | F14: 1576 | G14: =15765.702+2998.82 -> 18764.522 | H14: 14327.69 | I14: =G14/H14 -> 1.3096683
A15: 1594 | B15: 39163.693 | C15: 41582.2 | D15: =B15/C15 -> 0.94183793 | F15: 1577 | G15: =8132.548+548.799 -> 8681.347 | H15: 10156.882 | I15: =G15/H15 -> 0.85472559
A16: 1596 | B16: 14658.045 | C16: 15986.995 | D16: =B16/C16 -> 0.91687306 | F16: 1578 | G16: 24147.108 | H16: 19966.773 | I16: =G16/H16 -> 1.2093646
A17: 1597 | B17: 29040.016 | C17: 26393.279 | D17: =B17/C17 -> 1.1002807
A18: 1598 | B18: 21535.43 | C18: 17980.56 | D18: =B18/C18 -> 1.1977063 | G18: =AVERAGE(G3:G17) -> 19040.789 | H18: =AVERAGE(H3:H17) -> 18383.146
A19: 1599 | B19: =33521.35+485.385 -> 34006.735 | C19: 42235.442 | D19: =B19/C19 -> 0.80517057 | I19: =AVERAGE(I3:I4) -> 1.1532972
A20: 1600 | B20: 33770.25 | C20: =27002.794+44.657 -> 27047.451 | D20: =B20/C20 -> 1.2485557
I21: =G18/H18 -> 1.0357743
A22: AVG | B22: =AVERAGE(B3:B20) -> 26319.194 | C22: =AVERAGE(C3:C20) -> 25544.333 | D22: =AVERAGE(D3:D20) -> 1.0473447
A24: ratio of avgs | D24: =B22/C22 -> 1.030334
